Workbook
Name 出力フォルダ: 設定!$C$5
Name 文字コード: 設定!$C$6
Name 引用符: 設定!$C$7
Name 法人名: 設定!$C$8
Name 事業主氏名: 設定!$C$9
Name 事業所_郵便番号: 設定!$C$10
Name 事業所_所在地: 設定!$C$11
Name 事業所_電話: 設定!$C$12
Name 事業所整理記号: 設定!$C$13
Name 事業所番号: 設定!$C$14
Name 雇保事業所番号: 設定!$C$15
Name 元号表: 設定!$B$20:$D$22
Name 届種別一覧: 設定!$B$27:$G$30
Name 届種別リスト: 設定!$B$27:$B$30
Name 入職台帳_DB先頭: '入職台帳'!$AG$4
Name 退職台帳_DB先頭: '退職台帳'!$Y$4
Name 届種別選択: 出力!$B$3
Name 入力氏名: チェックリスト!$D$4
Name 入力区分: チェックリスト!$D$5
Name 入力基準日: チェックリスト!$D$6
Name 入力生年月日: チェックリスト!$D$7
Name 入力国籍: チェックリスト!$D$8
Name 入力在留資格: チェックリスト!$D$9
Name 入力社保: チェックリスト!$D$10
Name 入力雇保: チェックリスト!$D$11
Name 入力扶養: チェックリスト!$D$12
Name 入力特徴: チェックリスト!$D$13
Name 入力共済: チェックリスト!$D$14
Name 入力役職: チェックリスト!$D$15
Name 入力離職票: チェックリスト!$D$16
Name 入力退職金: チェックリスト!$D$17
Name 入力障害者: チェックリスト!$D$18
Name 入力退職理由: チェックリスト!$D$19
Name 条件_社保: チェックリスト!$J$4
Name 条件_雇保: チェックリスト!$J$5
Name 条件_外国籍: チェックリスト!$J$6
Name 条件_特定技能: チェックリスト!$J$7
Name 条件_扶養: チェックリスト!$J$8
Name 条件_70歳以上: チェックリスト!$J$9
Name 条件_離職票要: チェックリスト!$J$10
Name 条件_特徴: チェックリスト!$J$11
Name 条件_共済: チェックリスト!$J$12
Name 条件_役職: チェックリスト!$J$13
Name 条件_退職金: チェックリスト!$J$14
Name 条件_障害者: チェックリスト!$J$15
Name 条件_解雇: チェックリスト!$J$16

Sheet 使い方
B2: 届出作成ツール v1.0（入退職の届出チェックリスト・届書データ作成）
B3: 色の約束：黄色＝入力する欄／緑＝自動（数式）／水色＝見出し・ボタン／灰色のシート＝ふだんは触らない
B5: ■ できること
B6: A. チェックリスト：1名分の条件を選ぶと、必要な届出・提出先・期限日が出る（印刷してそのまま使える）
B7: B. 届書データ：入職台帳／退職台帳の○を付けた行から、社保の取得届・喪失届のCSV、雇保の取得届・喪失届の転記一覧を作る
B9: ■ 毎回の流れ（届書データ）
B10: 1. 入退職管理マスタの入職DB（退職DB）から対象者の行をコピーし、台帳の「DB貼り付け欄」に【値で貼り付け】する（Ctrl+Alt+V → 値）
B11: 2. 台帳の黄色の「追加入力」列（性別・報酬月額など）を埋め、出力したい行のA列に○を付ける
B12: 3. 「出力」シートで届種別を選び［チェック］→ 下の一覧にエラーが出たら台帳を直す
B13: 4. エラー0件になったら［CSV出力］。社保はCSVファイル、雇保は「内容確認」シートの転記一覧ができる
B14: 5. 社保：届書作成プログラムでCSVを読み込み、個人番号を入力して電子申請。雇保：転記一覧を見てe-Gov等に入力
B15: 6. 提出が済んだら台帳の［台帳をクリア］で個人データを消してから保存する（実データを残したまま保存しない）
... B25: ・詳しくは 運用手順書（届出作成ツール）を参照

Sheet 出力
A1: 出力（届書データの作成）
A2: ①届種別を選ぶ ②［チェック］ ③エラー0件なら［CSV出力］
A3: 届種別 | B3: 社保取得
A4: 対象台帳 | B4: =IFERROR(INDEX(届種別一覧,MATCH($B$3,届種別リスト,0),2),"")
A5: 出力形式／確定 | B5: =IFERROR(INDEX(届種別一覧,MATCH($B$3,届種別リスト,0),3)&"／"&INDEX(届種別一覧,MATCH($B$3,届種別リスト,0),5),"")
A6: メッセージ
A8: ボタンがないとき：Alt+F8 で btnCheck／btnExport を実行（初回は SetupButtons を1回実行するとボタンが付く）
A10: 区分 | B10: 台帳行 | C10: 職員番号 | D10: 氏名 | E10: 項目 | F10: 内容

Sheet 入職台帳
A1: 入職台帳（採用者）
A2: ①DB貼り付け欄に入退職管理マスタの行を【値で貼り付け】 ②黄色の追加入力を埋める ③出力する行のA列に○
A3: 自動・出力管理 | E3: 追加入力（黄色）：DBにない届書の項目 | AG3: DB貼り付け欄：入退職管理マスタの行を値で貼り付け（見出しが変わったら4行目も貼り直す）
A4: 出力対象 | B4: 出力済 | C4: 職員番号（表示） | D4: 氏名（表示） | E4: 性別 | F4: 基礎年金番号 | G4: 被扶養者 | H4: 報酬月額_通貨 | I4: 報酬月額_現物 | J4: 報酬月額_合計 | K4: 社保備考区分 | L4: 郵便番号 | M4: 住所カナ | N4: 住所 | O4: 氏名ローマ字 | P4: 雇保取得区分 | Q4: 雇保被保険者番号 | R4: 取得原因 | S4: 賃金支払態様 | T4: 賃金月額 | U4: 雇用形態 | V4: 職種区分 | W4: 就職経路 | X4: 週所定労働時間 | Y4: 契約期間の定め | Z4: 契約開始日 | AA4: 契約更新条項 | AB4: 国籍・地域 | AC4: 資格外活動許可 | AD4: 派遣・請負就労区分 | AE4: 在留カード番号 | AG4: No. | AH4: 年度 | AI4: 入職年月 | AJ4: 区分 | AK4: 入職日 ★必須 | AL4: 職員番号 ★必須 | AM4: 氏名 ★必須 | AN4: フリガナ | AO4: 事業所 ★選択 | AP4: 事業所 コード | AQ4: 職種 ★選択 | AR4: 職種 コード | AS4: 保有資格 ★選択 | AT4: 雇用区分 ★選択 | AU4: 雇用区分 コード | AV4: 在留資格 区分★ | AW4: 採用経路 ★選択 | AX4: 紹介会社・ 媒体名 | AY4: 夜勤宿直 ★選択 | AZ4: 契約満了日 (有期のみ) | BA4: 更新 | BB4: 社会保険 ★選択 | BC4: 雇用保険 ★選択 | BD4: マイカー通勤 ★選択 | BE4: 手続 ステータス | BF4: 進捗率 | BG4: 健診 受診日 | BH4: 健診結果 受領 | BI4: 職員登録票 | BJ4: 誓約書 | BK4: 扶養控除 申告書 | BL4: マイカー 誓約書 | BM4: マイカー 申請 | BN4: マイカー 提出書類 | BO4: マイナンバー 確認 | BP4: 資格者証 (写) | BQ4: 源泉徴収票 (前職) | BR4: 社保 加入手続 | BS4: 資格確認書 交付 | BT4: 社保 (扶養数) | BU4: 社保 受取 | BV4: 保険証 番号 | BW4: 本人受取 (社保) | BX4: 社保区分 ★選択 | BY4: 雇保 資格取得届出日 | BZ4: 本人受取 (雇保) | CA4: 入職時 説明・ 契約者 | CB4: 雇用契約書 | CC4: 人事通知書 (辞令) | CD4: 名札 | CE4: 互助会 | CF4: IC発行 番号 | CG4: システム登録 (ミロク) | CH4: システム登録 (ND) | CI4: 備考 | CJ4: 対象手続数 | CK4: 名札表記 ★入力 | CL4: 制服サイズ ★選択 | CM4: 在留期限 (外国籍のみ) | CN4: 生年月日 ★入力 | CO4: 入職時 年齢 | CP4: 現在 年齢 | CQ4: 雇用契約 担当者★選択 | CR4: 社保取得 手続★選択 | CS4: 雇保取得 手続★選択 | CT4: 現所属 (自動) | CU4: 在籍状況 (自動) | CV4: イレギュラー 対応メモ
A5: ○ | C5: =IFERROR(INDEX($AG5:$GA5,MATCH("職員番号*",$AG$4:$GA$4,0))&"","") | D5: =IFERROR(INDEX($AG5:$GA5,MATCH("氏名*",$AG$4:$GA$4,0))&"","") | E5: 男 | G5: 有 | H5: 250000 | I5: 0 | J5: =IF(AND(H5="",I5=""),"",N(H5)+N(I5)) | P5: 新規 | R5: 新規雇用（その他） | S5: 月給 | T5: 250000 | U5: その他 | V5: サービスの職業 | W5: 安定所紹介 | X5: 40 | Y5: 無 | AG5: 1 | AH5: R08 | AI5: 2026/11 | AJ5: 入職 | AK5: 46327 | AL5: D001 | AM5: 山田 太郎 | AN5: ヤマダ タロウ | AO5: 特養A | AP5: 001 | AQ5: 介護職員 | AR5: 001 | AS5: 介護福祉士 | AT5: 正規職員 | AU5: 001 | AW5: ハローワーク | AY5: 有 | BB5: 加入 | BC5: 加入 | BD5: 該当 | BE5: 手続中 | BX5: 一般 | CN5: 33005 | CT5: 特養A | CU5: 在籍中
A6: ○ | C6: =IFERROR(INDEX($AG6:$GA6,MATCH("職員番号*",$AG$4:$GA$4,0))&"","") | D6: =IFERROR(INDEX($AG6:$GA6,MATCH("氏名*",$AG$4:$GA$4,0))&"","") | E6: 女 | G6: 無 | H6: 210000 | I6: 0 | J6: =IF(AND(H6="",I6=""),"",N(H6)+N(I6)) | O6: NGUYEN THI HOA | P6: 新規 | R6: 新規雇用（その他） | S6: 月給 | T6: 210000 | U6: 有期契約労働者 | V6: サービスの職業 | W6: 民間紹介 | X6: 40 | Y6: 有 | Z6: 46327 | AA6: 有 | AB6: ベトナム | AC6: 無 | AD6: 非該当 | AE6: AB12345678CD | AG6: 2 | AH6: R08 | AI6: 2026/11 | AJ6: 入職 | AK6: 46327 | AL6: D002 | AM6: グエン ティホア | AN6: グエン ティホア | AO6: 特養A | AP6: 001 | AQ6: 介護職員 | AR6: 001 | AS6: 無資格 | AT6: 準職員 | AU6: 002 | AV6: 特定技能 | AW6: 紹介会社 | AX6: ダミー紹介社 | AY6: 有 | AZ6: 46691 | BA6: 有 | BB6: 加入 | BC6: 加入 | BD6: 非該当 | BE6: 手続中 | BX6: 一般 | CM6: 46691 | CN6: 35829 | CT6: 特養A | CU6: 在籍中
A7: ○ | C7: =IFERROR(INDEX($AG7:$GA7,MATCH("職員番号*",$AG$4:$GA$4,0))&"","") | D7: =IFERROR(INDEX($AG7:$GA7,MATCH("氏名*",$AG$4:$GA$4,0))&"","") | E7: 女 | G7: 無 | H7: 120000 | I7: 0 | J7: =IF(AND(H7="",I7=""),"",N(H7)+N(I7)) | K7: 70歳以上被用者該当 | P7: 新規 | R7: 新規雇用（その他） | S7: 時間給 | T7: 120000 | U7: パートタイム | V7: 事務的職業 | W7: 自己就職 | X7: 25 | Y7: 有 | Z7: 46342 | AA7: 有 | AG7: 3 | AH7: R08 | AI7: 2026/11 | AJ7: 入職 | AK7: 46342 | AL7: D003 | AM7: 佐藤 花子 | AN7: さとう はなこ | AO7: 事務局 | AP7: 009 | AQ7: 事務員 | AR7: 010 | AS7: 無資格 | AT7: パート | AU7: 004 | AW7: 知人紹介 | AY7: 無 | AZ7: 46477 | BA7: 有 | BB7: 加入 | BC7: 加入 | BE7: 手続中 | BX7: 一般 | CN7: 20321 | CT7: 事務局 | CU7: 在籍中
C8: =IFERROR(INDEX($AG8:$GA8,MATCH("職員番号*",$AG$4:$GA$4,0))&"","") | D8: =IFERROR(INDEX($AG8:$GA8,MATCH("氏名*",$AG$4:$GA$4,0))&"","") | J8: =IF(AND(H8="",I8=""),"",N(H8)+N(I8))
C9: =IFERROR(INDEX($AG9:$GA9,MATCH("職員番号*",$AG$4:$GA$4,0))&"","") | D9: =IFERROR(INDEX($AG9:$GA9,MATCH("氏名*",$AG$4:$GA$4,0))&"","") | J9: =IF(AND(H9="",I9=""),"",N(H9)+N(I9))
C10: =IFERROR(INDEX($AG10:$GA10,MATCH("職員番号*",$AG$4:$GA$4,0))&"","") | D10: =IFERROR(INDEX($AG10:$GA10,MATCH("氏名*",$AG$4:$GA$4,0))&"","") | J10: =IF(AND(H10="",I10=""),"",N(H10)+N(I10))
C11: =IFERROR(INDEX($AG11:$GA11,MATCH("職員番号*",$AG$4:$GA$4,0))&"","") | D11: =IFERROR(INDEX($AG11:$GA11,MATCH("氏名*",$AG$4:$GA$4,0))&"","") | J11: =IF(AND(H11="",I11=""),"",N(H11)+N(I11))
C12: =IFERROR(INDEX($AG12:$GA12,MATCH("職員番号*",$AG$4:$GA$4,0))&"","") | D12: =IFERROR(INDEX($AG12:$GA12,MATCH("氏名*",$AG$4:$GA$4,0))&"","") | J12: =IF(AND(H12="",I12=""),"",N(H12)+N(I12))
C13: =IFERROR(INDEX($AG13:$GA13,MATCH("職員番号*",$AG$4:$GA$4,0))&"","") | D13: =IFERROR(INDEX($AG13:$GA13,MATCH("氏名*",$AG$4:$GA$4,0))&"","") | J13: =IF(AND(H13="",I13=""),"",N(H13)+N(I13))
C14: =IFERROR(INDEX($AG14:$GA14,MATCH("職員番号*",$AG$4:$GA$4,0))&"","") | D14: =IFERROR(INDEX($AG14:$GA14,MATCH("氏名*",$AG$4:$GA$4,0))&"","") | J14: =IF(AND(H14="",I14=""),"",N(H14)+N(I14))
C15: =IFERROR(INDEX($AG15:$GA15,MATCH("職員番号*",$AG$4:$GA$4,0))&"","") | D15: =IFERROR(INDEX($AG15:$GA15,MATCH("氏名*",$AG$4:$GA$4,0))&"","") | J15: =IF(AND(H15="",I15=""),"",N(H15)+N(I15))
C16: =IFERROR(INDEX($AG16:$GA16,MATCH("職員番号*",$AG$4:$GA$4,0))&"","") | D16: =IFERROR(INDEX($AG16:$GA16,MATCH("氏名*",$AG$4:$GA$4,0))&"","") | J16: =IF(AND(H16="",I16=""),"",N(H16)+N(I16))
C17: =IFERROR(INDEX($AG17:$GA17,MATCH("職員番号*",$AG$4:$GA$4,0))&"","") | D17: =IFERROR(INDEX($AG17:$GA17,MATCH("氏名*",$AG$4:$GA$4,0))&"","") | J17: =IF(AND(H17="",I17=""),"",N(H17)+N(I17))
C18: =IFERROR(INDEX($AG18:$GA18,MATCH("職員番号*",$AG$4:$GA$4,0))&"","") | D18: =IFERROR(INDEX($AG18:$GA18,MATCH("氏名*",$AG$4:$GA$4,0))&"","") | J18: =IF(AND(H18="",I18=""),"",N(H18)+N(I18))
C19: =IFERROR(INDEX($AG19:$GA19,MATCH("職員番号*",$AG$4:$GA$4,0))&"","") | D19: =IFERROR(INDEX($AG19:$GA19,MATCH("氏名*",$AG$4:$GA$4,0))&"","") | J19: =IF(AND(H19="",I19=""),"",N(H19)+N(I19))
... C204: =IFERROR(INDEX($AG204:$GA204,MATCH("職員番号*",$AG$4:$GA$4,0))&"","") | D204: =IFERROR(INDEX($AG204:$GA204,MATCH("氏名*",$AG$4:$GA$4,0))&"","") | J204: =IF(AND(H204="",I204=""),"",N(H204)+N(I204))

Sheet 退職台帳
A1: 退職台帳（退職者）
A2: ①DB貼り付け欄に入退職管理マスタの行を【値で貼り付け】 ②黄色の追加入力を埋める ③出力する行のA列に○
A3: 自動・出力管理 | E3: 追加入力（黄色）：DBにない届書の項目 | Y3: DB貼り付け欄：入退職管理マスタの行を値で貼り付け（見出しが変わったら4行目も貼り直す）
A4: 出力対象 | B4: 出力済 | C4: 職員番号（表示） | D4: 氏名（表示） | E4: フリガナ | F4: 生年月日 | G4: 性別 | H4: 被保険者整理番号 | I4: 基礎年金番号 | J4: 社保喪失原因 | K4: 社保喪失備考 | L4: 70歳以上不該当 | M4: 雇保被保険者番号 | N4: 雇保喪失原因 | O4: 離職票交付希望 | P4: 週所定労働時間 | Q4: 補充採用予定 | R4: 住所 | S4: 氏名ローマ字 | T4: 国籍・地域 | U4: 在留期間満了日 | V4: 派遣・請負就労区分 | W4: 在留カード番号 | Y4: No. | Z4: 年度 | AA4: 退職年月 | AB4: 退職日 ★必須 | AC4: 職員番号 ★必須 | AD4: 氏名 ★必須 | AE4: 事業所 ★選択 | AF4: 事業所 コード | AG4: 職種 ★選択 | AH4: 雇用区分 ★選択 | AI4: 在留資格 区分★ | AJ4: 入職日 ★必須 | AK4: 勤続年数 | AL4: 勤続区分 | AM4: 退職区分 ★選択 | AN4: 退職理由1 ★選択 | AO4: 退職理由2 | AP4: 退職理由3 | AQ4: 退職事由 補足 | AR4: 再雇用 可否 | AS4: 手続 ステータス | AT4: 進捗率 | AU4: 退職届 受理 | AV4: 社保 資格喪失 | AW4: 扶養 | AX4: 70歳以上被用者不該当届 | AY4: 保険証等 回収 | AZ4: 高齢受給者証 | BA4: 離職証明書 提出日 | BB4: 離職票 交付 | BC4: 社保喪失 手続★選択 | BD4: 雇保喪失 手続★選択
A5: ○ | C5: =IFERROR(INDEX($Y5:$FS5,MATCH("職員番号*",$Y$4:$FS$4,0))&"","") | D5: =IFERROR(INDEX($Y5:$FS5,MATCH("氏名*",$Y$4:$FS$4,0))&"","") | E5: スズキ イチロウ | F5: 31077 | G5: 男 | H5: 123 | J5: 退職等 | L5: 無 | M5: 9999-999999-9 | N5: 3以外の離職 | O5: 有 | P5: 40 | Q5: 有 | R5: 長野県ダミー市ダミー町1-2-3 | Y5: 1 | Z5: R08 | AA5: 2026/11 | AB5: 46356 | AC5: D004 | AD5: 鈴木 一郎 | AE5: デイB | AF5: 002 | AG5: 生活相談員 | AH5: 正規職員 | AJ5: 42095 | AK5: 11.7 | AL5: 10年以上 | AM5: 自己都合 | AN5: 03.転職 | AR5: 可 | AS5: 手続中 | AU5: 済 | AX5: 対象外
A6: ○ | C6: =IFERROR(INDEX($Y6:$FS6,MATCH("職員番号*",$Y$4:$FS$4,0))&"","") | D6: =IFERROR(INDEX($Y6:$FS6,MATCH("氏名*",$Y$4:$FS$4,0))&"","") | E6: タカハシ サクラ | F6: 33792 | G6: 女 | Y6: 2 | Z6: R08 | AA6: 2026/11 | AB6: 46341 | AC6: D005 | AD6: 高橋 さくら | AE6: 訪問C | AF6: 003 | AG6: サービス提供責任者 | AH6: パート | AJ6: 45444 | AK6: 2.5 | AL6: 1年以上3年未満 | AM6: 自己都合 | AN6: 01.家庭の事情 | AR6: 可 | AS6: 手続中 | AU6: 済 | AV6: 対象外 | AX6: 対象外 | BC6: 対象外 | BD6: 対象外
C7: =IFERROR(INDEX($Y7:$FS7,MATCH("職員番号*",$Y$4:$FS$4,0))&"","") | D7: =IFERROR(INDEX($Y7:$FS7,MATCH("氏名*",$Y$4:$FS$4,0))&"","")
C8: =IFERROR(INDEX($Y8:$FS8,MATCH("職員番号*",$Y$4:$FS$4,0))&"","") | D8: =IFERROR(INDEX($Y8:$FS8,MATCH("氏名*",$Y$4:$FS$4,0))&"","")
C9: =IFERROR(INDEX($Y9:$FS9,MATCH("職員番号*",$Y$4:$FS$4,0))&"","") | D9: =IFERROR(INDEX($Y9:$FS9,MATCH("氏名*",$Y$4:$FS$4,0))&"","")
C10: =IFERROR(INDEX($Y10:$FS10,MATCH("職員番号*",$Y$4:$FS$4,0))&"","") | D10: =IFERROR(INDEX($Y10:$FS10,MATCH("氏名*",$Y$4:$FS$4,0))&"","")
C11: =IFERROR(INDEX($Y11:$FS11,MATCH("職員番号*",$Y$4:$FS$4,0))&"","") | D11: =IFERROR(INDEX($Y11:$FS11,MATCH("氏名*",$Y$4:$FS$4,0))&"","")
C12: =IFERROR(INDEX($Y12:$FS12,MATCH("職員番号*",$Y$4:$FS$4,0))&"","") | D12: =IFERROR(INDEX($Y12:$FS12,MATCH("氏名*",$Y$4:$FS$4,0))&"","")
C13: =IFERROR(INDEX($Y13:$FS13,MATCH("職員番号*",$Y$4:$FS$4,0))&"","") | D13: =IFERROR(INDEX($Y13:$FS13,MATCH("氏名*",$Y$4:$FS$4,0))&"","")
C14: =IFERROR(INDEX($Y14:$FS14,MATCH("職員番号*",$Y$4:$FS$4,0))&"","") | D14: =IFERROR(INDEX($Y14:$FS14,MATCH("氏名*",$Y$4:$FS$4,0))&"","")
C15: =IFERROR(INDEX($Y15:$FS15,MATCH("職員番号*",$Y$4:$FS$4,0))&"","") | D15: =IFERROR(INDEX($Y15:$FS15,MATCH("氏名*",$Y$4:$FS$4,0))&"","")
C16: =IFERROR(INDEX($Y16:$FS16,MATCH("職員番号*",$Y$4:$FS$4,0))&"","") | D16: =IFERROR(INDEX($Y16:$FS16,MATCH("氏名*",$Y$4:$FS$4,0))&"","")
C17: =IFERROR(INDEX($Y17:$FS17,MATCH("職員番号*",$Y$4:$FS$4,0))&"","") | D17: =IFERROR(INDEX($Y17:$FS17,MATCH("氏名*",$Y$4:$FS$4,0))&"","")
C18: =IFERROR(INDEX($Y18:$FS18,MATCH("職員番号*",$Y$4:$FS$4,0))&"","") | D18: =IFERROR(INDEX($Y18:$FS18,MATCH("氏名*",$Y$4:$FS$4,0))&"","")
... C204: =IFERROR(INDEX($Y204:$FS204,MATCH("職員番号*",$Y$4:$FS$4,0))&"","") | D204: =IFERROR(INDEX($Y204:$FS204,MATCH("氏名*",$Y$4:$FS$4,0))&"","")

Sheet チェックリスト
B1: 届出チェックリスト
B2: 黄色の欄を選ぶと、必要な届出と期限日が下に出る（A4縦で印刷）
I3: 判定用（触らない）
C4: 氏名（ダミー可） | I4: 社保 | J4: =IF(入力社保="有","有","無")
C5: 区分 | I5: 雇保 | J5: =IF(入力雇保="有","有","無")
C6: 基準日（採用日／退職日） | I6: 外国籍 | J6: =IF(入力国籍="外国籍","有","無")
C7: 生年月日 | I7: 特定技能 | J7: =IF(入力在留資格="特定技能","有","無")
C8: 国籍 | I8: 扶養 | J8: =IF(入力扶養="有","有","無")
C9: 在留資格 | I9: 70歳以上 | J9: =IF(AND(ISNUMBER(入力生年月日),ISNUMBER(入力基準日)),IF(DATEDIF(入力生年月日,入力基準日,"Y")>=70,"有","無"),"無")
C10: 社会保険（健保・厚年）に加入 | I10: 離職票要 | J10: =IF(OR(入力離職票="有",AND(ISNUMBER(入力生年月日),ISNUMBER(入力基準日),DATEDIF(入力生年月日,入力基準日,"Y")>=59)),"有","無")
C11: 雇用保険に加入 | I11: 特徴 | J11: =IF(入力特徴="有","有","無")
C12: 扶養家族（採用時） | I12: 共済 | J12: =IF(入力共済="有","有","無")
C13: 住民税 特別徴収 | I13: 役職 | J13: =IF(入力役職="有","有","無")
C14: 退職手当共済（WAM）の対象 | I14: 退職金 | J14: =IF(入力退職金="有","有","無")
C15: 人員基準上の役職者 | I15: 障害者 | J15: =IF(入力障害者="有","有","無")
C16: 離職票の希望（退職時） | I16: 解雇 | J16: =IF(入力退職理由="解雇","有","無")
C17: 退職金の支給（退職時） | I17: 年齢 | J17: =IF(AND(ISNUMBER(入力生年月日),ISNUMBER(入力基準日)),DATEDIF(入力生年月日,入力基準日,"Y"),"")
C18: 障害者雇用
C19: 退職理由（退職時）
B21: ■ 必要な届出（期限は安全側＝早めの日付。最終確認は各提出先で）
C22: 届出名 | D22: 届出先 | E22: 期限 | F22: 作成方法・備考 | G22: 完了日
B23: =IF(C23="","","☐") | C23: =IFERROR(INDEX(ルール!$B$5:$B$64,MATCH(1,ルール!$Y$5:$Y$64,0)),"") | D23: =IFERROR(INDEX(ルール!$C$5:$C$64,MATCH(1,ルール!$Y$5:$Y$64,0)),"") | E23: =IFERROR(INDEX(ルール!$Z$5:$Z$64,MATCH(1,ルール!$Y$5:$Y$64,0)),"") | F23: =IFERROR(INDEX(ルール!$V$5:$V$64,MATCH(1,ルール!$Y$5:$Y$64,0))&IF(INDEX(ルール!$W$5:$W$64,MATCH(1,ルール!$Y$5:$Y$64,0))="","","（"&INDEX(ルール!$W$5:$W$64,MATCH(1,ルール!$Y$5:$Y$64,0))&"）"),"")
B24: =IF(C24="","","☐") | C24: =IFERROR(INDEX(ルール!$B$5:$B$64,MATCH(2,ルール!$Y$5:$Y$64,0)),"") | D24: =IFERROR(INDEX(ルール!$C$5:$C$64,MATCH(2,ルール!$Y$5:$Y$64,0)),"") | E24: =IFERROR(INDEX(ルール!$Z$5:$Z$64,MATCH(2,ルール!$Y$5:$Y$64,0)),"") | F24: =IFERROR(INDEX(ルール!$V$5:$V$64,MATCH(2,ルール!$Y$5:$Y$64,0))&IF(INDEX(ルール!$W$5:$W$64,MATCH(2,ルール!$Y$5:$Y$64,0))="","","（"&INDEX(ルール!$W$5:$W$64,MATCH(2,ルール!$Y$5:$Y$64,0))&"）"),"")
B25: =IF(C25="","","☐") | C25: =IFERROR(INDEX(ルール!$B$5:$B$64,MATCH(3,ルール!$Y$5:$Y$64,0)),"") | D25: =IFERROR(INDEX(ルール!$C$5:$C$64,MATCH(3,ルール!$Y$5:$Y$64,0)),"") | E25: =IFERROR(INDEX(ルール!$Z$5:$Z$64,MATCH(3,ルール!$Y$5:$Y$64,0)),"") | F25: =IFERROR(INDEX(ルール!$V$5:$V$64,MATCH(3,ルール!$Y$5:$Y$64,0))&IF(INDEX(ルール!$W$5:$W$64,MATCH(3,ルール!$Y$5:$Y$64,0))="","","（"&INDEX(ルール!$W$5:$W$64,MATCH(3,ルール!$Y$5:$Y$64,0))&"）"),"")
B26: =IF(C26="","","☐") | C26: =IFERROR(INDEX(ルール!$B$5:$B$64,MATCH(4,ルール!$Y$5:$Y$64,0)),"") | D26: =IFERROR(INDEX(ルール!$C$5:$C$64,MATCH(4,ルール!$Y$5:$Y$64,0)),"") | E26: =IFERROR(INDEX(ルール!$Z$5:$Z$64,MATCH(4,ルール!$Y$5:$Y$64,0)),"") | F26: =IFERROR(INDEX(ルール!$V$5:$V$64,MATCH(4,ルール!$Y$5:$Y$64,0))&IF(INDEX(ルール!$W$5:$W$64,MATCH(4,ルール!$Y$5:$Y$64,0))="","","（"&INDEX(ルール!$W$5:$W$64,MATCH(4,ルール!$Y$5:$Y$64,0))&"）"),"")
B27: =IF(C27="","","☐") | C27: =IFERROR(INDEX(ルール!$B$5:$B$64,MATCH(5,ルール!$Y$5:$Y$64,0)),"") | D27: =IFERROR(INDEX(ルール!$C$5:$C$64,MATCH(5,ルール!$Y$5:$Y$64,0)),"") | E27: =IFERROR(INDEX(ルール!$Z$5:$Z$64,MATCH(5,ルール!$Y$5:$Y$64,0)),"") | F27: =IFERROR(INDEX(ルール!$V$5:$V$64,MATCH(5,ルール!$Y$5:$Y$64,0))&IF(INDEX(ルール!$W$5:$W$64,MATCH(5,ルール!$Y$5:$Y$64,0))="","","（"&INDEX(ルール!$W$5:$W$64,MATCH(5,ルール!$Y$5:$Y$64,0))&"）"),"")
B28: =IF(C28="","","☐") | C28: =IFERROR(INDEX(ルール!$B$5:$B$64,MATCH(6,ルール!$Y$5:$Y$64,0)),"") | D28: =IFERROR(INDEX(ルール!$C$5:$C$64,MATCH(6,ルール!$Y$5:$Y$64,0)),"") | E28: =IFERROR(INDEX(ルール!$Z$5:$Z$64,MATCH(6,ルール!$Y$5:$Y$64,0)),"") | F28: =IFERROR(INDEX(ルール!$V$5:$V$64,MATCH(6,ルール!$Y$5:$Y$64,0))&IF(INDEX(ルール!$W$5:$W$64,MATCH(6,ルール!$Y$5:$Y$64,0))="","","（"&INDEX(ルール!$W$5:$W$64,MATCH(6,ルール!$Y$5:$Y$64,0))&"）"),"")
B29: =IF(C29="","","☐") | C29: =IFERROR(INDEX(ルール!$B$5:$B$64,MATCH(7,ルール!$Y$5:$Y$64,0)),"") | D29: =IFERROR(INDEX(ルール!$C$5:$C$64,MATCH(7,ルール!$Y$5:$Y$64,0)),"") | E29: =IFERROR(INDEX(ルール!$Z$5:$Z$64,MATCH(7,ルール!$Y$5:$Y$64,0)),"") | F29: =IFERROR(INDEX(ルール!$V$5:$V$64,MATCH(7,ルール!$Y$5:$Y$64,0))&IF(INDEX(ルール!$W$5:$W$64,MATCH(7,ルール!$Y$5:$Y$64,0))="","","（"&INDEX(ルール!$W$5:$W$64,MATCH(7,ルール!$Y$5:$Y$64,0))&"）"),"")
B30: =IF(C30="","","☐") | C30: =IFERROR(INDEX(ルール!$B$5:$B$64,MATCH(8,ルール!$Y$5:$Y$64,0)),"") | D30: =IFERROR(INDEX(ルール!$C$5:$C$64,MATCH(8,ルール!$Y$5:$Y$64,0)),"") | E30: =IFERROR(INDEX(ルール!$Z$5:$Z$64,MATCH(8,ルール!$Y$5:$Y$64,0)),"") | F30: =IFERROR(INDEX(ルール!$V$5:$V$64,MATCH(8,ルール!$Y$5:$Y$64,0))&IF(INDEX(ルール!$W$5:$W$64,MATCH(8,ルール!$Y$5:$Y$64,0))="","","（"&INDEX(ルール!$W$5:$W$64,MATCH(8,ルール!$Y$5:$Y$64,0))&"）"),"")
B31: =IF(C31="","","☐") | C31: =IFERROR(INDEX(ルール!$B$5:$B$64,MATCH(9,ルール!$Y$5:$Y$64,0)),"") | D31: =IFERROR(INDEX(ルール!$C$5:$C$64,MATCH(9,ルール!$Y$5:$Y$64,0)),"") | E31: =IFERROR(INDEX(ルール!$Z$5:$Z$64,MATCH(9,ルール!$Y$5:$Y$64,0)),"") | F31: =IFERROR(INDEX(ルール!$V$5:$V$64,MATCH(9,ルール!$Y$5:$Y$64,0))&IF(INDEX(ルール!$W$5:$W$64,MATCH(9,ルール!$Y$5:$Y$64,0))="","","（"&INDEX(ルール!$W$5:$W$64,MATCH(9,ルール!$Y$5:$Y$64,0))&"）"),"")
B32: =IF(C32="","","☐") | C32: =IFERROR(INDEX(ルール!$B$5:$B$64,MATCH(10,ルール!$Y$5:$Y$64,0)),"") | D32: =IFERROR(INDEX(ルール!$C$5:$C$64,MATCH(10,ルール!$Y$5:$Y$64,0)),"") | E32: =IFERROR(INDEX(ルール!$Z$5:$Z$64,MATCH(10,ルール!$Y$5:$Y$64,0)),"") | F32: =IFERROR(INDEX(ルール!$V$5:$V$64,MATCH(10,ルール!$Y$5:$Y$64,0))&IF(INDEX(ルール!$W$5:$W$64,MATCH(10,ルール!$Y$5:$Y$64,0))="","","（"&INDEX(ルール!$W$5:$W$64,MATCH(10,ルール!$Y$5:$Y$64,0))&"）"),"")
B33: =IF(C33="","","☐") | C33: =IFERROR(INDEX(ルール!$B$5:$B$64,MATCH(11,ルール!$Y$5:$Y$64,0)),"") | D33: =IFERROR(INDEX(ルール!$C$5:$C$64,MATCH(11,ルール!$Y$5:$Y$64,0)),"") | E33: =IFERROR(INDEX(ルール!$Z$5:$Z$64,MATCH(11,ルール!$Y$5:$Y$64,0)),"") | F33: =IFERROR(INDEX(ルール!$V$5:$V$64,MATCH(11,ルール!$Y$5:$Y$64,0))&IF(INDEX(ルール!$W$5:$W$64,MATCH(11,ルール!$Y$5:$Y$64,0))="","","（"&INDEX(ルール!$W$5:$W$64,MATCH(11,ルール!$Y$5:$Y$64,0))&"）"),"")
B34: =IF(C34="","","☐") | C34: =IFERROR(INDEX(ルール!$B$5:$B$64,MATCH(12,ルール!$Y$5:$Y$64,0)),"") | D34: =IFERROR(INDEX(ルール!$C$5:$C$64,MATCH(12,ルール!$Y$5:$Y$64,0)),"") | E34: =IFERROR(INDEX(ルール!$Z$5:$Z$64,MATCH(12,ルール!$Y$5:$Y$64,0)),"") | F34: =IFERROR(INDEX(ルール!$V$5:$V$64,MATCH(12,ルール!$Y$5:$Y$64,0))&IF(INDEX(ルール!$W$5:$W$64,MATCH(12,ルール!$Y$5:$Y$64,0))="","","（"&INDEX(ルール!$W$5:$W$64,MATCH(12,ルール!$Y$5:$Y$64,0))&"）"),"")
B35: =IF(C35="","","☐") | C35: =IFERROR(INDEX(ルール!$B$5:$B$64,MATCH(13,ルール!$Y$5:$Y$64,0)),"") | D35: =IFERROR(INDEX(ルール!$C$5:$C$64,MATCH(13,ルール!$Y$5:$Y$64,0)),"") | E35: =IFERROR(INDEX(ルール!$Z$5:$Z$64,MATCH(13,ルール!$Y$5:$Y$64,0)),"") | F35: =IFERROR(INDEX(ルール!$V$5:$V$64,MATCH(13,ルール!$Y$5:$Y$64,0))&IF(INDEX(ルール!$W$5:$W$64,MATCH(13,ルール!$Y$5:$Y$64,0))="","","（"&INDEX(ルール!$W$5:$W$64,MATCH(13,ルール!$Y$5:$Y$64,0))&"）"),"")
B36: =IF(C36="","","☐") | C36: =IFERROR(INDEX(ルール!$B$5:$B$64,MATCH(14,ルール!$Y$5:$Y$64,0)),"") | D36: =IFERROR(INDEX(ルール!$C$5:$C$64,MATCH(14,ルール!$Y$5:$Y$64,0)),"") | E36: =IFERROR(INDEX(ルール!$Z$5:$Z$64,MATCH(14,ルール!$Y$5:$Y$64,0)),"") | F36: =IFERROR(INDEX(ルール!$V$5:$V$64,MATCH(14,ルール!$Y$5:$Y$64,0))&IF(INDEX(ルール!$W$5:$W$64,MATCH(14,ルール!$Y$5:$Y$64,0))="","","（"&INDEX(ルール!$W$5:$W$64,MATCH(14,ルール!$Y$5:$Y$64,0))&"）"),"")
B37: =IF(C37="","","☐") | C37: =IFERROR(INDEX(ルール!$B$5:$B$64,MATCH(15,ルール!$Y$5:$Y$64,0)),"") | D37: =IFERROR(INDEX(ルール!$C$5:$C$64,MATCH(15,ルール!$Y$5:$Y$64,0)),"") | E37: =IFERROR(INDEX(ルール!$Z$5:$Z$64,MATCH(15,ルール!$Y$5:$Y$64,0)),"") | F37: =IFERROR(INDEX(ルール!$V$5:$V$64,MATCH(15,ルール!$Y$5:$Y$64,0))&IF(INDEX(ルール!$W$5:$W$64,MATCH(15,ルール!$Y$5:$Y$64,0))="","","（"&INDEX(ルール!$W$5:$W$64,MATCH(15,ルール!$Y$5:$Y$64,0))&"）"),"")
B38: =IF(C38="","","☐") | C38: =IFERROR(INDEX(ルール!$B$5:$B$64,MATCH(16,ルール!$Y$5:$Y$64,0)),"") | D38: =IFERROR(INDEX(ルール!$C$5:$C$64,MATCH(16,ルール!$Y$5:$Y$64,0)),"") | E38: =IFERROR(INDEX(ルール!$Z$5:$Z$64,MATCH(16,ルール!$Y$5:$Y$64,0)),"") | F38: =IFERROR(INDEX(ルール!$V$5:$V$64,MATCH(16,ルール!$Y$5:$Y$64,0))&IF(INDEX(ルール!$W$5:$W$64,MATCH(16,ルール!$Y$5:$Y$64,0))="","","（"&INDEX(ルール!$W$5:$W$64,MATCH(16,ルール!$Y$5:$Y$64,0))&"）"),"")
B39: =IF(C39="","","☐") | C39: =IFERROR(INDEX(ルール!$B$5:$B$64,MATCH(17,ルール!$Y$5:$Y$64,0)),"") | D39: =IFERROR(INDEX(ルール!$C$5:$C$64,MATCH(17,ルール!$Y$5:$Y$64,0)),"") | E39: =IFERROR(INDEX(ルール!$Z$5:$Z$64,MATCH(17,ルール!$Y$5:$Y$64,0)),"") | F39: =IFERROR(INDEX(ルール!$V$5:$V$64,MATCH(17,ルール!$Y$5:$Y$64,0))&IF(INDEX(ルール!$W$5:$W$64,MATCH(17,ルール!$Y$5:$Y$64,0))="","","（"&INDEX(ルール!$W$5:$W$64,MATCH(17,ルール!$Y$5:$Y$64,0))&"）"),"")
B40: =IF(C40="","","☐") | C40: =IFERROR(INDEX(ルール!$B$5:$B$64,MATCH(18,ルール!$Y$5:$Y$64,0)),"") | D40: =IFERROR(INDEX(ルール!$C$5:$C$64,MATCH(18,ルール!$Y$5:$Y$64,0)),"") | E40: =IFERROR(INDEX(ルール!$Z$5:$Z$64,MATCH(18,ルール!$Y$5:$Y$64,0)),"") | F40: =IFERROR(INDEX(ルール!$V$5:$V$64,MATCH(18,ルール!$Y$5:$Y$64,0))&IF(INDEX(ルール!$W$5:$W$64,MATCH(18,ルール!$Y$5:$Y$64,0))="","","（"&INDEX(ルール!$W$5:$W$64,MATCH(18,ルール!$Y$5:$Y$64,0))&"）"),"")
B41: =IF(C41="","","☐") | C41: =IFERROR(INDEX(ルール!$B$5:$B$64,MATCH(19,ルール!$Y$5:$Y$64,0)),"") | D41: =IFERROR(INDEX(ルール!$C$5:$C$64,MATCH(19,ルール!$Y$5:$Y$64,0)),"") | E41: =IFERROR(INDEX(ルール!$Z$5:$Z$64,MATCH(19,ルール!$Y$5:$Y$64,0)),"") | F41: =IFERROR(INDEX(ルール!$V$5:$V$64,MATCH(19,ルール!$Y$5:$Y$64,0))&IF(INDEX(ルール!$W$5:$W$64,MATCH(19,ルール!$Y$5:$Y$64,0))="","","（"&INDEX(ルール!$W$5:$W$64,MATCH(19,ルール!$Y$5:$Y$64,0))&"）"),"")
...

Sheet 内容確認
A1: 内容確認・転記一覧
A2: ［チェック］［CSV出力］のたびに作り直される。雇保はこの表を見てe-Gov等に入力する
A3: ※ 個人データが入る。提出後は台帳と一緒にクリアする（次回のチェックで上書きされる）

Sheet 設定
A1: 設定（初回と変更時のみ）
A2: 黄色の欄を実際の値に差し替える。ダミー値のまま提出しない
B4: 項目（名前） | C4: 値 | D4: 説明
B5: 出力フォルダ | D5: 空欄＝このブックと同じ場所の「出力」フォルダ。人事部のみアクセスできる場所にする
B6: 文字コード | C6: Shift_JIS | D6: CSV仕様書に合わせる（Shift_JIS／UTF-8）
B7: 引用符 | C7: しない | D7: 各項目を " で囲むか（する／しない）。CSV仕様書に合わせる
B8: 法人名 | C8: 社会福祉法人○○会（要入力）
B9: 事業主氏名 | C9: 理事長 ○○ ○○（要入力）
B10: 事業所_郵便番号 | C10: 000-0000 | D10: ダミー値
B11: 事業所_所在地 | C11: 長野県○○市○○（要入力）
B12: 事業所_電話 | C12: 0000-00-0000 | D12: ダミー値
B13: 事業所整理記号 | C13: 99ﾀﾞﾐ | D13: 健保・厚年の事業所整理記号（ダミー値）。法人で1つ
B14: 事業所番号 | C14: 99999 | D14: 健保・厚年の事業所番号（ダミー値）
B15: 雇保事業所番号 | C15: 9999-999999-9 | D15: 雇用保険の適用事業所番号（ダミー値）。法人で1つ
B18: ■ 元号表（和暦の変換に使う）
B19: 元号 | C19: 開始日 | D19: コード（CSV用） | E19: コードは届書様式の元号番号（5=昭和 7=平成 9=令和）。CSV仕様書で要確認
B20: 昭和 | C20: 9856 | D20: 5
B21: 平成 | C21: 32516 | D21: 7
B22: 令和 | C22: 43586 | D22: 9
B25: ■ 届種別一覧（出力シートの選択肢）
B26: 届種別 | C26: 対象台帳 | D26: 出力形式 | E26: ファイル名 | F26: 確定 | G26: 対象条件 | H26: 説明
B27: 社保取得 | C27: 入職台帳 | D27: CSV | F27: 未 | G27: 社会保険=加入 | H27: 届書作成プログラムに読み込むCSV
B28: 社保喪失 | C28: 退職台帳 | D28: CSV | F28: 未 | G28: 社保資格喪失<>対象外 | H28: 退職DBの「社保 資格喪失」が対象外の人は除く
B29: 雇保取得 | C29: 入職台帳 | D29: 転記一覧 | F29: 未 | G29: 雇用保険=加入 | H29: 届書作成プログラムのCSV取込に対応と確認できたらCSVに変更
B30: 雇保喪失 | C30: 退職台帳 | D30: 転記一覧 | F30: 未 | G30: 雇保喪失手続<>対象外 | H30: 同上
B31: 確定＝CSV仕様書と突き合わせ、届書作成プログラムで取込エラー0を確認したら「済」にする。ファイル名＝仕様書で決まっていれば入れる（毎回新しいフォルダに作る）
B32: 対象条件＝「列名=値」「列名<>値」。○を付けた行のうち、条件に合う行だけを出力する

Sheet レイアウト定義
A1: レイアウト定義（CSV・転記一覧の項目の並び）
A2: 1行＝1項目。CSV仕様書が変わったらここを直す（マクロは直さない）。M列に「重複」と出たら順番を直す
A4: 届種別 | B4: 行種別 | C4: 順番 | D4: 項目名 | E4: 取得元 | F4: 固定値 | G4: 書式 | H4: 桁数 | I4: 必須 | J4: 変換 | K4: 条件 | L4: 備考 | M4: 重複チェック
A5: 社保取得 | B5: 明細 | C5: 1 | D5: 届書コード | E5: 固定 | G5: 文字 | I5: ○ | L5: 要確認：仕様書のレコード識別子（届書コード）を入れる | M5: =IF(A5="","",IF(COUNTIFS($A$5:$A$305,A5,$B$5:$B$305,B5,$C$5:$C$305,C5)>1,"重複",""))
A6: 社保取得 | B6: 明細 | C6: 2 | D6: 事業所整理記号 | E6: 設定:事業所整理記号 | G6: 文字 | I6: ○ | L6: 要確認：CSV仕様書で順番・桁数・書式を確認 | M6: =IF(A6="","",IF(COUNTIFS($A$5:$A$305,A6,$B$5:$B$305,B6,$C$5:$C$305,C6)>1,"重複",""))
A7: 社保取得 | B7: 明細 | C7: 3 | D7: 事業所番号 | E7: 設定:事業所番号 | G7: 文字 | I7: ○ | L7: 要確認：CSV仕様書で順番・桁数・書式を確認 | M7: =IF(A7="","",IF(COUNTIFS($A$5:$A$305,A7,$B$5:$B$305,B7,$C$5:$C$305,C7)>1,"重複",""))
A8: 社保取得 | B8: 明細 | C8: 4 | D8: 被保険者整理番号 | E8: 台帳:保険証番号 | G8: 文字 | J8: 数字のみ | L8: 任意。空欄時の扱いは仕様書で確認 | M8: =IF(A8="","",IF(COUNTIFS($A$5:$A$305,A8,$B$5:$B$305,B8,$C$5:$C$305,C8)>1,"重複",""))
A9: 社保取得 | B9: 明細 | C9: 5 | D9: 被保険者氏名カナ（氏） | E9: 台帳:フリガナ | G9: 文字 | I9: ○ | J9: 全角カナ+姓 | L9: 要確認：CSV仕様書で順番・桁数・書式を確認（半角カナ指定の可能性） | M9: =IF(A9="","",IF(COUNTIFS($A$5:$A$305,A9,$B$5:$B$305,B9,$C$5:$C$305,C9)>1,"重複",""))
A10: 社保取得 | B10: 明細 | C10: 6 | D10: 被保険者氏名カナ（名） | E10: 台帳:フリガナ | G10: 文字 | I10: ○ | J10: 全角カナ+名 | L10: 要確認：CSV仕様書で順番・桁数・書式を確認 | M10: =IF(A10="","",IF(COUNTIFS($A$5:$A$305,A10,$B$5:$B$305,B10,$C$5:$C$305,C10)>1,"重複",""))
A11: 社保取得 | B11: 明細 | C11: 7 | D11: 被保険者氏名（氏） | E11: 台帳:氏名 | G11: 文字 | I11: ○ | J11: 姓 | L11: 要確認：CSV仕様書で順番・桁数・書式を確認 | M11: =IF(A11="","",IF(COUNTIFS($A$5:$A$305,A11,$B$5:$B$305,B11,$C$5:$C$305,C11)>1,"重複",""))
A12: 社保取得 | B12: 明細 | C12: 8 | D12: 被保険者氏名（名） | E12: 台帳:氏名 | G12: 文字 | I12: ○ | J12: 名 | L12: 要確認：CSV仕様書で順番・桁数・書式を確認 | M12: =IF(A12="","",IF(COUNTIFS($A$5:$A$305,A12,$B$5:$B$305,B12,$C$5:$C$305,C12)>1,"重複",""))
A13: 社保取得 | B13: 明細 | C13: 9 | D13: 生年月日 | E13: 台帳:生年月日 | G13: 和暦7 | I13: ○ | L13: 要確認：CSV仕様書で順番・桁数・書式を確認（元号と年月日を分ける場合は2行に分け「元号コード」「和暦6」） | M13: =IF(A13="","",IF(COUNTIFS($A$5:$A$305,A13,$B$5:$B$305,B13,$C$5:$C$305,C13)>1,"重複",""))
A14: 社保取得 | B14: 明細 | C14: 10 | D14: 種別 | E14: 台帳:性別 | G14: 文字 | I14: ○ | J14: コード表:社保種別 | L14: 要確認：CSV仕様書で順番・桁数・書式を確認 | M14: =IF(A14="","",IF(COUNTIFS($A$5:$A$305,A14,$B$5:$B$305,B14,$C$5:$C$305,C14)>1,"重複",""))
A15: 社保取得 | B15: 明細 | C15: 11 | D15: 取得区分 | E15: 固定 | F15: 1 | G15: 文字 | I15: ○ | L15: 様式の番号（1=健保・厚年）。要確認：CSV仕様書で順番・桁数・書式を確認 | M15: =IF(A15="","",IF(COUNTIFS($A$5:$A$305,A15,$B$5:$B$305,B15,$C$5:$C$305,C15)>1,"重複",""))
A16: 社保取得 | B16: 明細 | C16: 12 | D16: 個人番号又は基礎年金番号 | E16: 台帳:基礎年金番号 | G16: 文字 | J16: 数字のみ | L16: マイナンバーはツールに入れない。空欄で出し、届書作成プログラム上で入力 | M16: =IF(A16="","",IF(COUNTIFS($A$5:$A$305,A16,$B$5:$B$305,B16,$C$5:$C$305,C16)>1,"重複",""))
A17: 社保取得 | B17: 明細 | C17: 13 | D17: 取得年月日 | E17: 台帳:入職日 | G17: 和暦7 | I17: ○ | L17: 要確認：CSV仕様書で順番・桁数・書式を確認 | M17: =IF(A17="","",IF(COUNTIFS($A$5:$A$305,A17,$B$5:$B$305,B17,$C$5:$C$305,C17)>1,"重複",""))
A18: 社保取得 | B18: 明細 | C18: 14 | D18: 被扶養者 | E18: 台帳:被扶養者 | G18: 文字 | I18: ○ | J18: コード表:有無01 | L18: 要確認：CSV仕様書で順番・桁数・書式を確認 | M18: =IF(A18="","",IF(COUNTIFS($A$5:$A$305,A18,$B$5:$B$305,B18,$C$5:$C$305,C18)>1,"重複",""))
A19: 社保取得 | B19: 明細 | C19: 15 | D19: 報酬月額（通貨） | E19: 台帳:報酬月額_通貨 | G19: 数値 | I19: ○ | L19: 要確認：CSV仕様書で順番・桁数・書式を確認 | M19: =IF(A19="","",IF(COUNTIFS($A$5:$A$305,A19,$B$5:$B$305,B19,$C$5:$C$305,C19)>1,"重複",""))
A20: 社保取得 | B20: 明細 | C20: 16 | D20: 報酬月額（現物） | E20: 台帳:報酬月額_現物 | G20: 数値 | L20: 要確認：CSV仕様書で順番・桁数・書式を確認 | M20: =IF(A20="","",IF(COUNTIFS($A$5:$A$305,A20,$B$5:$B$305,B20,$C$5:$C$305,C20)>1,"重複",""))
A21: 社保取得 | B21: 明細 | C21: 17 | D21: 報酬月額（合計） | E21: 台帳:報酬月額_合計 | G21: 数値 | I21: ○ | L21: 要確認：CSV仕様書で順番・桁数・書式を確認 | M21: =IF(A21="","",IF(COUNTIFS($A$5:$A$305,A21,$B$5:$B$305,B21,$C$5:$C$305,C21)>1,"重複",""))
A22: 社保取得 | B22: 明細 | C22: 18 | D22: 備考 | E22: 台帳:社保備考区分 | G22: 文字 | J22: コード表:社保備考 | L22: 要確認：CSV仕様書で順番・桁数・書式を確認 | M22: =IF(A22="","",IF(COUNTIFS($A$5:$A$305,A22,$B$5:$B$305,B22,$C$5:$C$305,C22)>1,"重複",""))
A23: 社保取得 | B23: 明細 | C23: 19 | D23: 郵便番号 | E23: 台帳:郵便番号 | G23: 文字 | I23: ○ | J23: 数字のみ | K23: 基礎年金番号<> | L23: 基礎年金番号で届け出る場合のみ必要 | M23: =IF(A23="","",IF(COUNTIFS($A$5:$A$305,A23,$B$5:$B$305,B23,$C$5:$C$305,C23)>1,"重複",""))
A24: 社保取得 | B24: 明細 | C24: 20 | D24: 住所（カナ） | E24: 台帳:住所カナ | G24: 文字 | I24: ○ | J24: 全角カナ | K24: 基礎年金番号<> | L24: 同上 | M24: =IF(A24="","",IF(COUNTIFS($A$5:$A$305,A24,$B$5:$B$305,B24,$C$5:$C$305,C24)>1,"重複",""))
A25: 社保取得 | B25: 明細 | C25: 21 | D25: 住所 | E25: 台帳:住所 | G25: 文字 | I25: ○ | K25: 基礎年金番号<> | L25: 同上 | M25: =IF(A25="","",IF(COUNTIFS($A$5:$A$305,A25,$B$5:$B$305,B25,$C$5:$C$305,C25)>1,"重複",""))
A26: 社保喪失 | B26: 明細 | C26: 1 | D26: 届書コード | E26: 固定 | G26: 文字 | I26: ○ | L26: 要確認：仕様書のレコード識別子（届書コード）を入れる | M26: =IF(A26="","",IF(COUNTIFS($A$5:$A$305,A26,$B$5:$B$305,B26,$C$5:$C$305,C26)>1,"重複",""))
A27: 社保喪失 | B27: 明細 | C27: 2 | D27: 事業所整理記号 | E27: 設定:事業所整理記号 | G27: 文字 | I27: ○ | L27: 要確認：CSV仕様書で順番・桁数・書式を確認 | M27: =IF(A27="","",IF(COUNTIFS($A$5:$A$305,A27,$B$5:$B$305,B27,$C$5:$C$305,C27)>1,"重複",""))
A28: 社保喪失 | B28: 明細 | C28: 3 | D28: 事業所番号 | E28: 設定:事業所番号 | G28: 文字 | I28: ○ | L28: 要確認：CSV仕様書で順番・桁数・書式を確認 | M28: =IF(A28="","",IF(COUNTIFS($A$5:$A$305,A28,$B$5:$B$305,B28,$C$5:$C$305,C28)>1,"重複",""))
A29: 社保喪失 | B29: 明細 | C29: 4 | D29: 被保険者整理番号 | E29: 台帳:被保険者整理番号 | G29: 文字 | I29: ○ | J29: 数字のみ | L29: 入職DBの「保険証番号」と同じ番号 | M29: =IF(A29="","",IF(COUNTIFS($A$5:$A$305,A29,$B$5:$B$305,B29,$C$5:$C$305,C29)>1,"重複",""))
A30: 社保喪失 | B30: 明細 | C30: 5 | D30: 被保険者氏名カナ（氏） | E30: 台帳:フリガナ | G30: 文字 | I30: ○ | J30: 全角カナ+姓 | L30: 要確認：CSV仕様書で順番・桁数・書式を確認 | M30: =IF(A30="","",IF(COUNTIFS($A$5:$A$305,A30,$B$5:$B$305,B30,$C$5:$C$305,C30)>1,"重複",""))
A31: 社保喪失 | B31: 明細 | C31: 6 | D31: 被保険者氏名カナ（名） | E31: 台帳:フリガナ | G31: 文字 | I31: ○ | J31: 全角カナ+名 | L31: 要確認：CSV仕様書で順番・桁数・書式を確認 | M31: =IF(A31="","",IF(COUNTIFS($A$5:$A$305,A31,$B$5:$B$305,B31,$C$5:$C$305,C31)>1,"重複",""))
A32: 社保喪失 | B32: 明細 | C32: 7 | D32: 被保険者氏名（氏） | E32: 台帳:氏名 | G32: 文字 | I32: ○ | J32: 姓 | L32: 要確認：CSV仕様書で順番・桁数・書式を確認 | M32: =IF(A32="","",IF(COUNTIFS($A$5:$A$305,A32,$B$5:$B$305,B32,$C$5:$C$305,C32)>1,"重複",""))
A33: 社保喪失 | B33: 明細 | C33: 8 | D33: 被保険者氏名（名） | E33: 台帳:氏名 | G33: 文字 | I33: ○ | J33: 名 | L33: 要確認：CSV仕様書で順番・桁数・書式を確認 | M33: =IF(A33="","",IF(COUNTIFS($A$5:$A$305,A33,$B$5:$B$305,B33,$C$5:$C$305,C33)>1,"重複",""))
A34: 社保喪失 | B34: 明細 | C34: 9 | D34: 生年月日 | E34: 台帳:生年月日 | G34: 和暦7 | I34: ○ | L34: 要確認：CSV仕様書で順番・桁数・書式を確認 | M34: =IF(A34="","",IF(COUNTIFS($A$5:$A$305,A34,$B$5:$B$305,B34,$C$5:$C$305,C34)>1,"重複",""))
A35: 社保喪失 | B35: 明細 | C35: 10 | D35: 個人番号又は基礎年金番号 | E35: 台帳:基礎年金番号 | G35: 文字 | J35: 数字のみ | L35: マイナンバーは届書作成プログラム上で入力 | M35: =IF(A35="","",IF(COUNTIFS($A$5:$A$305,A35,$B$5:$B$305,B35,$C$5:$C$305,C35)>1,"重複",""))
A36: 社保喪失 | B36: 明細 | C36: 11 | D36: 喪失年月日 | E36: 台帳:退職日 | G36: 和暦7 | I36: ○ | J36: 翌日 | L36: 退職日の翌日。死亡は死亡日の翌日 | M36: =IF(A36="","",IF(COUNTIFS($A$5:$A$305,A36,$B$5:$B$305,B36,$C$5:$C$305,C36)>1,"重複",""))
A37: 社保喪失 | B37: 明細 | C37: 12 | D37: 喪失原因 | E37: 台帳:社保喪失原因 | G37: 文字 | I37: ○ | J37: コード表:社保喪失原因 | L37: 要確認：CSV仕様書で順番・桁数・書式を確認 | M37: =IF(A37="","",IF(COUNTIFS($A$5:$A$305,A37,$B$5:$B$305,B37,$C$5:$C$305,C37)>1,"重複",""))
A38: 社保喪失 | B38: 明細 | C38: 13 | D38: 退職等年月日 | E38: 台帳:退職日 | G38: 和暦7 | I38: ○ | K38: 社保喪失原因=退職等 | L38: 要確認：CSV仕様書で順番・桁数・書式を確認 | M38: =IF(A38="","",IF(COUNTIFS($A$5:$A$305,A38,$B$5:$B$305,B38,$C$5:$C$305,C38)>1,"重複",""))
A39: 社保喪失 | B39: 明細 | C39: 14 | D39: 備考 | E39: 台帳:社保喪失備考 | G39: 文字 | J39: コード表:社保喪失備考 | L39: 要確認：CSV仕様書で順番・桁数・書式を確認 | M39: =IF(A39="","",IF(COUNTIFS($A$5:$A$305,A39,$B$5:$B$305,B39,$C$5:$C$305,C39)>1,"重複",""))
A40: 社保喪失 | B40: 明細 | C40: 15 | D40: 70歳以上被用者不該当 | E40: 固定 | F40: 1 | G40: 文字 | K40: 70歳以上不該当=有 | L40: 要確認：CSV仕様書で順番・桁数・書式を確認 | M40: =IF(A40="","",IF(COUNTIFS($A$5:$A$305,A40,$B$5:$B$305,B40,$C$5:$C$305,C40)>1,"重複",""))
A41: 社保喪失 | B41: 明細 | C41: 16 | D41: 不該当年月日 | E41: 台帳:退職日 | G41: 和暦7 | I41: ○ | K41: 70歳以上不該当=有 | L41: 要確認：CSV仕様書で順番・桁数・書式を確認 | M41: =IF(A41="","",IF(COUNTIFS($A$5:$A$305,A41,$B$5:$B$305,B41,$C$5:$C$305,C41)>1,"重複",""))
...

Sheet コード表
A1: コード表（表示値 → CSVコード）
A2: レイアウト定義の変換「コード表:区分名」で使う。CSVコードが空の行を選ぶとエラーになる
A4: 区分 | B4: 表示値 | C4: CSVコード | D4: 備考
A5: 社保種別 | B5: 男 | C5: 1 | D5: 届書様式の番号。CSV仕様書で要確認
A6: 社保種別 | B6: 女 | C6: 2 | D6: 届書様式の番号。CSV仕様書で要確認
A7: 有無01 | B7: 無 | C7: 0 | D7: 届書様式の番号。CSV仕様書で要確認
A8: 有無01 | B8: 有 | C8: 1 | D8: 届書様式の番号。CSV仕様書で要確認
A9: 社保備考 | B9: 70歳以上被用者該当 | C9: 1 | D9: 届書様式の番号。CSV仕様書で要確認
A10: 社保備考 | B10: 二以上事業所勤務者の取得 | C10: 2 | D10: 届書様式の番号。CSV仕様書で要確認
A11: 社保備考 | B11: 短時間労働者の取得 | C11: 3 | D11: 届書様式の番号。CSV仕様書で要確認
A12: 社保備考 | B12: 退職後の継続再雇用者の取得 | C12: 4 | D12: 届書様式の番号。CSV仕様書で要確認
A13: 社保備考 | B13: その他 | C13: 5 | D13: 届書様式の番号。CSV仕様書で要確認
A14: 社保喪失原因 | B14: 退職等 | C14: 4 | D14: 届書様式の番号。CSV仕様書で要確認
A15: 社保喪失原因 | B15: 死亡 | C15: 5 | D15: 届書様式の番号。CSV仕様書で要確認
... A17: 社保喪失原因 | B17: 障害認定 | C17: 9 | D17: 届書様式の番号。CSV仕様書で要確認
A18: 社保喪失備考 | B18: 二以上事業所勤務者の喪失 | D18: 未入力（要確認）。選ぶとエラーになる
A19: 社保喪失備考 | B19: 退職後の継続再雇用者の喪失 | D19: 未入力（要確認）
A20: 社保喪失備考 | B20: その他 | D20: 未入力（要確認）

Sheet ルール
A1: ルール（チェックリストの判定表）
A2: 条件列：空欄＝問わない／有・無＝その値のときだけ該当。行を足せば届出を追加できる（緑の数式は下までコピー済み）
A4: No | B4: 届出名 | C4: 届出先 | D4: 場面 | E4: 社保 | F4: 雇保 | G4: 外国籍 | H4: 特定技能 | I4: 扶養 | J4: 70歳以上 | K4: 離職票要 | L4: 特徴 | M4: 共済 | N4: 役職 | O4: 退職金 | P4: 障害者 | Q4: 解雇 | R4: 加算方式 | S4: 起算 | T4: 日数 | U4: 期限文言 | V4: 作成方法 | W4: 備考 | X4: 該当 | Y4: 該当番号 | Z4: 期限
A5: 1 | B5: 健保・厚年 資格取得届 | C5: 年金事務所 | D5: 採用 | E5: 有 | R5: 日数 | S5: 0 | T5: 5 | V5: 本ツール（社保取得） | W5: 入職日を1日目として5日以内 | X5: =AND($B5<>"",入力区分<>"",OR($D5="両方",$D5=入力区分),OR($E5="",$E5=条件_社保),OR($F5="",$F5=条件_雇保),OR($G5="",$G5=条件_外国籍),OR($H5="",$H5=条件_特定技能),OR($I5="",$I5=条件_扶養),OR($J5="",$J5=条件_70歳以上),OR($K5="",$K5=条件_離職票要),OR($L5="",$L5=条件_特徴),OR($M5="",$M5=条件_共済),OR($N5="",$N5=条件_役職),OR($O5="",$O5=条件_退職金),OR($P5="",$P5=条件_障害者),OR($Q5="",$Q5=条件_解雇)) | Y5: =IF($X5,COUNTIF($X$5:$X5,TRUE),"") | Z5: =IF(NOT($X5),"",IF($R5="文言",$U5,IF(入力基準日="","基準日を入力",IF($R5="日数",入力基準日+$S5+$T5-1,IF($R5="翌月10日",EOMONTH(入力基準日,0)+10,IF($R5="翌月末",EOMONTH(入力基準日,1),IF($R5="1か月後",EDATE(入力基準日,1),$U5)))))))
A6: 2 | B6: 被扶養者（異動）届／国民年金第3号被保険者関係届 | C6: 年金事務所 | D6: 採用 | E6: 有 | I6: 有 | R6: 日数 | S6: 0 | T6: 5 | V6: 届書作成プログラム | W6: 続柄・収入の確認は人が行う | X6: =AND($B6<>"",入力区分<>"",OR($D6="両方",$D6=入力区分),OR($E6="",$E6=条件_社保),OR($F6="",$F6=条件_雇保),OR($G6="",$G6=条件_外国籍),OR($H6="",$H6=条件_特定技能),OR($I6="",$I6=条件_扶養),OR($J6="",$J6=条件_70歳以上),OR($K6="",$K6=条件_離職票要),OR($L6="",$L6=条件_特徴),OR($M6="",$M6=条件_共済),OR($N6="",$N6=条件_役職),OR($O6="",$O6=条件_退職金),OR($P6="",$P6=条件_障害者),OR($Q6="",$Q6=条件_解雇)) | Y6: =IF($X6,COUNTIF($X$5:$X6,TRUE),"") | Z6: =IF(NOT($X6),"",IF($R6="文言",$U6,IF(入力基準日="","基準日を入力",IF($R6="日数",入力基準日+$S6+$T6-1,IF($R6="翌月10日",EOMONTH(入力基準日,0)+10,IF($R6="翌月末",EOMONTH(入力基準日,1),IF($R6="1か月後",EDATE(入力基準日,1),$U6)))))))
A7: 3 | B7: 70歳以上被用者 該当届 | C7: 年金事務所 | D7: 採用 | E7: 有 | J7: 有 | R7: 日数 | S7: 0 | T7: 5 | V7: 取得届と同じ様式 | W7: 台帳の社保備考区分で「70歳以上被用者該当」を選ぶ | X7: =AND($B7<>"",入力区分<>"",OR($D7="両方",$D7=入力区分),OR($E7="",$E7=条件_社保),OR($F7="",$F7=条件_雇保),OR($G7="",$G7=条件_外国籍),OR($H7="",$H7=条件_特定技能),OR($I7="",$I7=条件_扶養),OR($J7="",$J7=条件_70歳以上),OR($K7="",$K7=条件_離職票要),OR($L7="",$L7=条件_特徴),OR($M7="",$M7=条件_共済),OR($N7="",$N7=条件_役職),OR($O7="",$O7=条件_退職金),OR($P7="",$P7=条件_障害者),OR($Q7="",$Q7=条件_解雇)) | Y7: =IF($X7,COUNTIF($X$5:$X7,TRUE),"") | Z7: =IF(NOT($X7),"",IF($R7="文言",$U7,IF(入力基準日="","基準日を入力",IF($R7="日数",入力基準日+$S7+$T7-1,IF($R7="翌月10日",EOMONTH(入力基準日,0)+10,IF($R7="翌月末",EOMONTH(入力基準日,1),IF($R7="1か月後",EDATE(入力基準日,1),$U7)))))))
A8: 4 | B8: ローマ字氏名届 | C8: 年金事務所 | D8: 採用 | E8: 有 | G8: 有 | R8: 日数 | S8: 0 | T8: 5 | V8: 取得届と同時（紙） | W8: 個人番号と基礎年金番号が結びつかない外国籍の人 | X8: =AND($B8<>"",入力区分<>"",OR($D8="両方",$D8=入力区分),OR($E8="",$E8=条件_社保),OR($F8="",$F8=条件_雇保),OR($G8="",$G8=条件_外国籍),OR($H8="",$H8=条件_特定技能),OR($I8="",$I8=条件_扶養),OR($J8="",$J8=条件_70歳以上),OR($K8="",$K8=条件_離職票要),OR($L8="",$L8=条件_特徴),OR($M8="",$M8=条件_共済),OR($N8="",$N8=条件_役職),OR($O8="",$O8=条件_退職金),OR($P8="",$P8=条件_障害者),OR($Q8="",$Q8=条件_解雇)) | Y8: =IF($X8,COUNTIF($X$5:$X8,TRUE),"") | Z8: =IF(NOT($X8),"",IF($R8="文言",$U8,IF(入力基準日="","基準日を入力",IF($R8="日数",入力基準日+$S8+$T8-1,IF($R8="翌月10日",EOMONTH(入力基準日,0)+10,IF($R8="翌月末",EOMONTH(入力基準日,1),IF($R8="1か月後",EDATE(入力基準日,1),$U8)))))))
A9: 5 | B9: 健保・厚年 資格喪失届 | C9: 年金事務所 | D9: 退職 | E9: 有 | R9: 日数 | S9: 1 | T9: 5 | V9: 本ツール（社保喪失） | W9: 喪失日（退職日の翌日）を1日目として5日以内 | X9: =AND($B9<>"",入力区分<>"",OR($D9="両方",$D9=入力区分),OR($E9="",$E9=条件_社保),OR($F9="",$F9=条件_雇保),OR($G9="",$G9=条件_外国籍),OR($H9="",$H9=条件_特定技能),OR($I9="",$I9=条件_扶養),OR($J9="",$J9=条件_70歳以上),OR($K9="",$K9=条件_離職票要),OR($L9="",$L9=条件_特徴),OR($M9="",$M9=条件_共済),OR($N9="",$N9=条件_役職),OR($O9="",$O9=条件_退職金),OR($P9="",$P9=条件_障害者),OR($Q9="",$Q9=条件_解雇)) | Y9: =IF($X9,COUNTIF($X$5:$X9,TRUE),"") | Z9: =IF(NOT($X9),"",IF($R9="文言",$U9,IF(入力基準日="","基準日を入力",IF($R9="日数",入力基準日+$S9+$T9-1,IF($R9="翌月10日",EOMONTH(入力基準日,0)+10,IF($R9="翌月末",EOMONTH(入力基準日,1),IF($R9="1か月後",EDATE(入力基準日,1),$U9)))))))
A10: 6 | B10: 70歳以上被用者 不該当届 | C10: 年金事務所 | D10: 退職 | E10: 有 | J10: 有 | R10: 日数 | S10: 1 | T10: 5 | V10: 喪失届と同じ様式 | X10: =AND($B10<>"",入力区分<>"",OR($D10="両方",$D10=入力区分),OR($E10="",$E10=条件_社保),OR($F10="",$F10=条件_雇保),OR($G10="",$G10=条件_外国籍),OR($H10="",$H10=条件_特定技能),OR($I10="",$I10=条件_扶養),OR($J10="",$J10=条件_70歳以上),OR($K10="",$K10=条件_離職票要),OR($L10="",$L10=条件_特徴),OR($M10="",$M10=条件_共済),OR($N10="",$N10=条件_役職),OR($O10="",$O10=条件_退職金),OR($P10="",$P10=条件_障害者),OR($Q10="",$Q10=条件_解雇)) | Y10: =IF($X10,COUNTIF($X$5:$X10,TRUE),"") | Z10: =IF(NOT($X10),"",IF($R10="文言",$U10,IF(入力基準日="","基準日を入力",IF($R10="日数",入力基準日+$S10+$T10-1,IF($R10="翌月10日",EOMONTH(入力基準日,0)+10,IF($R10="翌月末",EOMONTH(入力基準日,1),IF($R10="1か月後",EDATE(入力基準日,1),$U10)))))))
A11: 7 | B11: 雇用保険 資格取得届 | C11: ハローワーク | D11: 採用 | F11: 有 | R11: 翌月10日 | S11: 0 | V11: 本ツール（雇保取得・転記一覧） | X11: =AND($B11<>"",入力区分<>"",OR($D11="両方",$D11=入力区分),OR($E11="",$E11=条件_社保),OR($F11="",$F11=条件_雇保),OR($G11="",$G11=条件_外国籍),OR($H11="",$H11=条件_特定技能),OR($I11="",$I11=条件_扶養),OR($J11="",$J11=条件_70歳以上),OR($K11="",$K11=条件_離職票要),OR($L11="",$L11=条件_特徴),OR($M11="",$M11=条件_共済),OR($N11="",$N11=条件_役職),OR($O11="",$O11=条件_退職金),OR($P11="",$P11=条件_障害者),OR($Q11="",$Q11=条件_解雇)) | Y11: =IF($X11,COUNTIF($X$5:$X11,TRUE),"") | Z11: =IF(NOT($X11),"",IF($R11="文言",$U11,IF(入力基準日="","基準日を入力",IF($R11="日数",入力基準日+$S11+$T11-1,IF($R11="翌月10日",EOMONTH(入力基準日,0)+10,IF($R11="翌月末",EOMONTH(入力基準日,1),IF($R11="1か月後",EDATE(入力基準日,1),$U11)))))))
A12: 8 | B12: 雇用保険 資格喪失届 | C12: ハローワーク | D12: 退職 | F12: 有 | R12: 日数 | S12: 2 | T12: 10 | V12: 本ツール（雇保喪失・転記一覧） | W12: 喪失日の翌日から10日以内 | X12: =AND($B12<>"",入力区分<>"",OR($D12="両方",$D12=入力区分),OR($E12="",$E12=条件_社保),OR($F12="",$F12=条件_雇保),OR($G12="",$G12=条件_外国籍),OR($H12="",$H12=条件_特定技能),OR($I12="",$I12=条件_扶養),OR($J12="",$J12=条件_70歳以上),OR($K12="",$K12=条件_離職票要),OR($L12="",$L12=条件_特徴),OR($M12="",$M12=条件_共済),OR($N12="",$N12=条件_役職),OR($O12="",$O12=条件_退職金),OR($P12="",$P12=条件_障害者),OR($Q12="",$Q12=条件_解雇)) | Y12: =IF($X12,COUNTIF($X$5:$X12,TRUE),"") | Z12: =IF(NOT($X12),"",IF($R12="文言",$U12,IF(入力基準日="","基準日を入力",IF($R12="日数",入力基準日+$S12+$T12-1,IF($R12="翌月10日",EOMONTH(入力基準日,0)+10,IF($R12="翌月末",EOMONTH(入力基準日,1),IF($R12="1か月後",EDATE(入力基準日,1),$U12)))))))
A13: 9 | B13: 雇用保険 離職証明書 | C13: ハローワーク | D13: 退職 | F13: 有 | K13: 有 | R13: 日数 | S13: 2 | T13: 10 | V13: 紙・MJS賃金データ | W13: 本人希望時／59歳以上は必須 | X13: =AND($B13<>"",入力区分<>"",OR($D13="両方",$D13=入力区分),OR($E13="",$E13=条件_社保),OR($F13="",$F13=条件_雇保),OR($G13="",$G13=条件_外国籍),OR($H13="",$H13=条件_特定技能),OR($I13="",$I13=条件_扶養),OR($J13="",$J13=条件_70歳以上),OR($K13="",$K13=条件_離職票要),OR($L13="",$L13=条件_特徴),OR($M13="",$M13=条件_共済),OR($N13="",$N13=条件_役職),OR($O13="",$O13=条件_退職金),OR($P13="",$P13=条件_障害者),OR($Q13="",$Q13=条件_解雇)) | Y13: =IF($X13,COUNTIF($X$5:$X13,TRUE),"") | Z13: =IF(NOT($X13),"",IF($R13="文言",$U13,IF(入力基準日="","基準日を入力",IF($R13="日数",入力基準日+$S13+$T13-1,IF($R13="翌月10日",EOMONTH(入力基準日,0)+10,IF($R13="翌月末",EOMONTH(入力基準日,1),IF($R13="1か月後",EDATE(入力基準日,1),$U13)))))))
A14: 10 | B14: 外国人雇用状況届出（雇保加入者） | C14: ハローワーク | D14: 両方 | F14: 有 | G14: 有 | R14: 文言 | U14: 取得届・喪失届と同時 | V14: 取得届・喪失届の外国人欄 | W14: 特別永住者は対象外 | X14: =AND($B14<>"",入力区分<>"",OR($D14="両方",$D14=入力区分),OR($E14="",$E14=条件_社保),OR($F14="",$F14=条件_雇保),OR($G14="",$G14=条件_外国籍),OR($H14="",$H14=条件_特定技能),OR($I14="",$I14=条件_扶養),OR($J14="",$J14=条件_70歳以上),OR($K14="",$K14=条件_離職票要),OR($L14="",$L14=条件_特徴),OR($M14="",$M14=条件_共済),OR($N14="",$N14=条件_役職),OR($O14="",$O14=条件_退職金),OR($P14="",$P14=条件_障害者),OR($Q14="",$Q14=条件_解雇)) | Y14: =IF($X14,COUNTIF($X$5:$X14,TRUE),"") | Z14: =IF(NOT($X14),"",IF($R14="文言",$U14,IF(入力基準日="","基準日を入力",IF($R14="日数",入力基準日+$S14+$T14-1,IF($R14="翌月10日",EOMONTH(入力基準日,0)+10,IF($R14="翌月末",EOMONTH(入力基準日,1),IF($R14="1か月後",EDATE(入力基準日,1),$U14)))))))
A15: 11 | B15: 外国人雇用状況届出（雇保非加入者） | C15: ハローワーク | D15: 両方 | F15: 無 | G15: 有 | R15: 翌月末 | V15: 外国人雇用状況届出（Web） | W15: 特別永住者は対象外 | X15: =AND($B15<>"",入力区分<>"",OR($D15="両方",$D15=入力区分),OR($E15="",$E15=条件_社保),OR($F15="",$F15=条件_雇保),OR($G15="",$G15=条件_外国籍),OR($H15="",$H15=条件_特定技能),OR($I15="",$I15=条件_扶養),OR($J15="",$J15=条件_70歳以上),OR($K15="",$K15=条件_離職票要),OR($L15="",$L15=条件_特徴),OR($M15="",$M15=条件_共済),OR($N15="",$N15=条件_役職),OR($O15="",$O15=条件_退職金),OR($P15="",$P15=条件_障害者),OR($Q15="",$Q15=条件_解雇)) | Y15: =IF($X15,COUNTIF($X$5:$X15,TRUE),"") | Z15: =IF(NOT($X15),"",IF($R15="文言",$U15,IF(入力基準日="","基準日を入力",IF($R15="日数",入力基準日+$S15+$T15-1,IF($R15="翌月10日",EOMONTH(入力基準日,0)+10,IF($R15="翌月末",EOMONTH(入力基準日,1),IF($R15="1か月後",EDATE(入力基準日,1),$U15)))))))
A16: 12 | B16: 特定技能雇用契約に係る届出（締結） | C16: 出入国在留管理局 | D16: 採用 | H16: 有 | R16: 日数 | S16: 0 | T16: 14 | V16: 参考様式（Excel） | W16: 在留資格変更許可申請で足りる場合あり。要否を確認 | X16: =AND($B16<>"",入力区分<>"",OR($D16="両方",$D16=入力区分),OR($E16="",$E16=条件_社保),OR($F16="",$F16=条件_雇保),OR($G16="",$G16=条件_外国籍),OR($H16="",$H16=条件_特定技能),OR($I16="",$I16=条件_扶養),OR($J16="",$J16=条件_70歳以上),OR($K16="",$K16=条件_離職票要),OR($L16="",$L16=条件_特徴),OR($M16="",$M16=条件_共済),OR($N16="",$N16=条件_役職),OR($O16="",$O16=条件_退職金),OR($P16="",$P16=条件_障害者),OR($Q16="",$Q16=条件_解雇)) | Y16: =IF($X16,COUNTIF($X$5:$X16,TRUE),"") | Z16: =IF(NOT($X16),"",IF($R16="文言",$U16,IF(入力基準日="","基準日を入力",IF($R16="日数",入力基準日+$S16+$T16-1,IF($R16="翌月10日",EOMONTH(入力基準日,0)+10,IF($R16="翌月末",EOMONTH(入力基準日,1),IF($R16="1か月後",EDATE(入力基準日,1),$U16)))))))
A17: 13 | B17: 特定技能雇用契約に係る届出（終了） | C17: 出入国在留管理局 | D17: 退職 | H17: 有 | R17: 日数 | S17: 0 | T17: 14 | V17: 参考様式（Excel） | X17: =AND($B17<>"",入力区分<>"",OR($D17="両方",$D17=入力区分),OR($E17="",$E17=条件_社保),OR($F17="",$F17=条件_雇保),OR($G17="",$G17=条件_外国籍),OR($H17="",$H17=条件_特定技能),OR($I17="",$I17=条件_扶養),OR($J17="",$J17=条件_70歳以上),OR($K17="",$K17=条件_離職票要),OR($L17="",$L17=条件_特徴),OR($M17="",$M17=条件_共済),OR($N17="",$N17=条件_役職),OR($O17="",$O17=条件_退職金),OR($P17="",$P17=条件_障害者),OR($Q17="",$Q17=条件_解雇)) | Y17: =IF($X17,COUNTIF($X$5:$X17,TRUE),"") | Z17: =IF(NOT($X17),"",IF($R17="文言",$U17,IF(入力基準日="","基準日を入力",IF($R17="日数",入力基準日+$S17+$T17-1,IF($R17="翌月10日",EOMONTH(入力基準日,0)+10,IF($R17="翌月末",EOMONTH(入力基準日,1),IF($R17="1か月後",EDATE(入力基準日,1),$U17)))))))
A18: 14 | B18: 受入れ困難に係る届出／支援計画変更届 | C18: 出入国在留管理局 | D18: 退職 | H18: 有 | R18: 日数 | S18: 0 | T18: 14 | V18: 参考様式（Excel） | W18: 理由の記載など判断を伴う | X18: =AND($B18<>"",入力区分<>"",OR($D18="両方",$D18=入力区分),OR($E18="",$E18=条件_社保),OR($F18="",$F18=条件_雇保),OR($G18="",$G18=条件_外国籍),OR($H18="",$H18=条件_特定技能),OR($I18="",$I18=条件_扶養),OR($J18="",$J18=条件_70歳以上),OR($K18="",$K18=条件_離職票要),OR($L18="",$L18=条件_特徴),OR($M18="",$M18=条件_共済),OR($N18="",$N18=条件_役職),OR($O18="",$O18=条件_退職金),OR($P18="",$P18=条件_障害者),OR($Q18="",$Q18=条件_解雇)) | Y18: =IF($X18,COUNTIF($X$5:$X18,TRUE),"") | Z18: =IF(NOT($X18),"",IF($R18="文言",$U18,IF(入力基準日="","基準日を入力",IF($R18="日数",入力基準日+$S18+$T18-1,IF($R18="翌月10日",EOMONTH(入力基準日,0)+10,IF($R18="翌月末",EOMONTH(入力基準日,1),IF($R18="1か月後",EDATE(入力基準日,1),$U18)))))))
A19: 15 | B19: 住民税 特別徴収への切替届出 | C19: 市町村 | D19: 採用 | L19: 有 | R19: 文言 | U19: 随時（早めに） | V19: 市町村の様式（紙） | W19: 市町村ごとに様式が違う | X19: =AND($B19<>"",入力区分<>"",OR($D19="両方",$D19=入力区分),OR($E19="",$E19=条件_社保),OR($F19="",$F19=条件_雇保),OR($G19="",$G19=条件_外国籍),OR($H19="",$H19=条件_特定技能),OR($I19="",$I19=条件_扶養),OR($J19="",$J19=条件_70歳以上),OR($K19="",$K19=条件_離職票要),OR($L19="",$L19=条件_特徴),OR($M19="",$M19=条件_共済),OR($N19="",$N19=条件_役職),OR($O19="",$O19=条件_退職金),OR($P19="",$P19=条件_障害者),OR($Q19="",$Q19=条件_解雇)) | Y19: =IF($X19,COUNTIF($X$5:$X19,TRUE),"") | Z19: =IF(NOT($X19),"",IF($R19="文言",$U19,IF(入力基準日="","基準日を入力",IF($R19="日数",入力基準日+$S19+$T19-1,IF($R19="翌月10日",EOMONTH(入力基準日,0)+10,IF($R19="翌月末",EOMONTH(入力基準日,1),IF($R19="1か月後",EDATE(入力基準日,1),$U19)))))))
A20: 16 | B20: 給与所得者異動届出書 | C20: 市町村 | D20: 退職 | L20: 有 | R20: 翌月10日 | S20: 0 | V20: 市町村の様式／eLTAX | X20: =AND($B20<>"",入力区分<>"",OR($D20="両方",$D20=入力区分),OR($E20="",$E20=条件_社保),OR($F20="",$F20=条件_雇保),OR($G20="",$G20=条件_外国籍),OR($H20="",$H20=条件_特定技能),OR($I20="",$I20=条件_扶養),OR($J20="",$J20=条件_70歳以上),OR($K20="",$K20=条件_離職票要),OR($L20="",$L20=条件_特徴),OR($M20="",$M20=条件_共済),OR($N20="",$N20=条件_役職),OR($O20="",$O20=条件_退職金),OR($P20="",$P20=条件_障害者),OR($Q20="",$Q20=条件_解雇)) | Y20: =IF($X20,COUNTIF($X$5:$X20,TRUE),"") | Z20: =IF(NOT($X20),"",IF($R20="文言",$U20,IF(入力基準日="","基準日を入力",IF($R20="日数",入力基準日+$S20+$T20-1,IF($R20="翌月10日",EOMONTH(入力基準日,0)+10,IF($R20="翌月末",EOMONTH(入力基準日,1),IF($R20="1か月後",EDATE(入力基準日,1),$U20)))))))
A21: 17 | B21: 退職手当共済 加入届 | C21: 福祉医療機構（WAM） | D21: 採用 | M21: 有 | R21: 文言 | U21: 共済規程で確認 | V21: WAM NET電子届出 | X21: =AND($B21<>"",入力区分<>"",OR($D21="両方",$D21=入力区分),OR($E21="",$E21=条件_社保),OR($F21="",$F21=条件_雇保),OR($G21="",$G21=条件_外国籍),OR($H21="",$H21=条件_特定技能),OR($I21="",$I21=条件_扶養),OR($J21="",$J21=条件_70歳以上),OR($K21="",$K21=条件_離職票要),OR($L21="",$L21=条件_特徴),OR($M21="",$M21=条件_共済),OR($N21="",$N21=条件_役職),OR($O21="",$O21=条件_退職金),OR($P21="",$P21=条件_障害者),OR($Q21="",$Q21=条件_解雇)) | Y21: =IF($X21,COUNTIF($X$5:$X21,TRUE),"") | Z21: =IF(NOT($X21),"",IF($R21="文言",$U21,IF(入力基準日="","基準日を入力",IF($R21="日数",入力基準日+$S21+$T21-1,IF($R21="翌月10日",EOMONTH(入力基準日,0)+10,IF($R21="翌月末",EOMONTH(入力基準日,1),IF($R21="1か月後",EDATE(入力基準日,1),$U21)))))))
A22: 18 | B22: 退職手当共済 退職届 | C22: 福祉医療機構（WAM） | D22: 退職 | M22: 有 | R22: 文言 | U22: 共済規程で確認 | V22: WAM NET電子届出 | X22: =AND($B22<>"",入力区分<>"",OR($D22="両方",$D22=入力区分),OR($E22="",$E22=条件_社保),OR($F22="",$F22=条件_雇保),OR($G22="",$G22=条件_外国籍),OR($H22="",$H22=条件_特定技能),OR($I22="",$I22=条件_扶養),OR($J22="",$J22=条件_70歳以上),OR($K22="",$K22=条件_離職票要),OR($L22="",$L22=条件_特徴),OR($M22="",$M22=条件_共済),OR($N22="",$N22=条件_役職),OR($O22="",$O22=条件_退職金),OR($P22="",$P22=条件_障害者),OR($Q22="",$Q22=条件_解雇)) | Y22: =IF($X22,COUNTIF($X$5:$X22,TRUE),"") | Z22: =IF(NOT($X22),"",IF($R22="文言",$U22,IF(入力基準日="","基準日を入力",IF($R22="日数",入力基準日+$S22+$T22-1,IF($R22="翌月10日",EOMONTH(入力基準日,0)+10,IF($R22="翌月末",EOMONTH(入力基準日,1),IF($R22="1か月後",EDATE(入力基準日,1),$U22)))))))
A23: 19 | B23: 退職手当金請求書（本人へ案内） | C23: 福祉医療機構（WAM） | D23: 退職 | M23: 有 | R23: 文言 | U23: 退職後（本人記入） | V23: 法人証明欄を記入 | W23: 加入期間1年以上の人 | X23: =AND($B23<>"",入力区分<>"",OR($D23="両方",$D23=入力区分),OR($E23="",$E23=条件_社保),OR($F23="",$F23=条件_雇保),OR($G23="",$G23=条件_外国籍),OR($H23="",$H23=条件_特定技能),OR($I23="",$I23=条件_扶養),OR($J23="",$J23=条件_70歳以上),OR($K23="",$K23=条件_離職票要),OR($L23="",$L23=条件_特徴),OR($M23="",$M23=条件_共済),OR($N23="",$N23=条件_役職),OR($O23="",$O23=条件_退職金),OR($P23="",$P23=条件_障害者),OR($Q23="",$Q23=条件_解雇)) | Y23: =IF($X23,COUNTIF($X$5:$X23,TRUE),"") | Z23: =IF(NOT($X23),"",IF($R23="文言",$U23,IF(入力基準日="","基準日を入力",IF($R23="日数",入力基準日+$S23+$T23-1,IF($R23="翌月10日",EOMONTH(入力基準日,0)+10,IF($R23="翌月末",EOMONTH(入力基準日,1),IF($R23="1か月後",EDATE(入力基準日,1),$U23)))))))
A24: 20 | B24: 指定権者への変更届（役職者の交代） | C24: 県・市町村 | D24: 両方 | N24: 有 | R24: 日数 | S24: 0 | T24: 10 | V24: 自治体の様式 | W24: 管理者・サビ管・サ責・介護支援専門員等 | X24: =AND($B24<>"",入力区分<>"",OR($D24="両方",$D24=入力区分),OR($E24="",$E24=条件_社保),OR($F24="",$F24=条件_雇保),OR($G24="",$G24=条件_外国籍),OR($H24="",$H24=条件_特定技能),OR($I24="",$I24=条件_扶養),OR($J24="",$J24=条件_70歳以上),OR($K24="",$K24=条件_離職票要),OR($L24="",$L24=条件_特徴),OR($M24="",$M24=条件_共済),OR($N24="",$N24=条件_役職),OR($O24="",$O24=条件_退職金),OR($P24="",$P24=条件_障害者),OR($Q24="",$Q24=条件_解雇)) | Y24: =IF($X24,COUNTIF($X$5:$X24,TRUE),"") | Z24: =IF(NOT($X24),"",IF($R24="文言",$U24,IF(入力基準日="","基準日を入力",IF($R24="日数",入力基準日+$S24+$T24-1,IF($R24="翌月10日",EOMONTH(入力基準日,0)+10,IF($R24="翌月末",EOMONTH(入力基準日,1),IF($R24="1か月後",EDATE(入力基準日,1),$U24)))))))
A25: 21 | B25: 体制届（加算要件が変わる場合） | C25: 県・市町村 | D25: 両方 | N25: 有 | R25: 文言 | U25: 算定月の前月15日等 | V25: 自治体の様式 | W25: 人員変動で加算要件が変わるか確認 | X25: =AND($B25<>"",入力区分<>"",OR($D25="両方",$D25=入力区分),OR($E25="",$E25=条件_社保),OR($F25="",$F25=条件_雇保),OR($G25="",$G25=条件_外国籍),OR($H25="",$H25=条件_特定技能),OR($I25="",$I25=条件_扶養),OR($J25="",$J25=条件_70歳以上),OR($K25="",$K25=条件_離職票要),OR($L25="",$L25=条件_特徴),OR($M25="",$M25=条件_共済),OR($N25="",$N25=条件_役職),OR($O25="",$O25=条件_退職金),OR($P25="",$P25=条件_障害者),OR($Q25="",$Q25=条件_解雇)) | Y25: =IF($X25,COUNTIF($X$5:$X25,TRUE),"") | Z25: =IF(NOT($X25),"",IF($R25="文言",$U25,IF(入力基準日="","基準日を入力",IF($R25="日数",入力基準日+$S25+$T25-1,IF($R25="翌月10日",EOMONTH(入力基準日,0)+10,IF($R25="翌月末",EOMONTH(入力基準日,1),IF($R25="1か月後",EDATE(入力基準日,1),$U25)))))))
A26: 22 | B26: 扶養控除等申告書（回収・保管） | C26: 法人保管 | D26: 採用 | R26: 文言 | U26: 初回給与支払まで | V26: 紙 | X26: =AND($B26<>"",入力区分<>"",OR($D26="両方",$D26=入力区分),OR($E26="",$E26=条件_社保),OR($F26="",$F26=条件_雇保),OR($G26="",$G26=条件_外国籍),OR($H26="",$H26=条件_特定技能),OR($I26="",$I26=条件_扶養),OR($J26="",$J26=条件_70歳以上),OR($K26="",$K26=条件_離職票要),OR($L26="",$L26=条件_特徴),OR($M26="",$M26=条件_共済),OR($N26="",$N26=条件_役職),OR($O26="",$O26=条件_退職金),OR($P26="",$P26=条件_障害者),OR($Q26="",$Q26=条件_解雇)) | Y26: =IF($X26,COUNTIF($X$5:$X26,TRUE),"") | Z26: =IF(NOT($X26),"",IF($R26="文言",$U26,IF(入力基準日="","基準日を入力",IF($R26="日数",入力基準日+$S26+$T26-1,IF($R26="翌月10日",EOMONTH(入力基準日,0)+10,IF($R26="翌月末",EOMONTH(入力基準日,1),IF($R26="1か月後",EDATE(入力基準日,1),$U26)))))))
A27: 23 | B27: 給与所得の源泉徴収票（本人交付） | C27: 本人 | D27: 退職 | R27: 1か月後 | S27: 0 | V27: 給与システム | W27: 退職後1か月以内 | X27: =AND($B27<>"",入力区分<>"",OR($D27="両方",$D27=入力区分),OR($E27="",$E27=条件_社保),OR($F27="",$F27=条件_雇保),OR($G27="",$G27=条件_外国籍),OR($H27="",$H27=条件_特定技能),OR($I27="",$I27=条件_扶養),OR($J27="",$J27=条件_70歳以上),OR($K27="",$K27=条件_離職票要),OR($L27="",$L27=条件_特徴),OR($M27="",$M27=条件_共済),OR($N27="",$N27=条件_役職),OR($O27="",$O27=条件_退職金),OR($P27="",$P27=条件_障害者),OR($Q27="",$Q27=条件_解雇)) | Y27: =IF($X27,COUNTIF($X$5:$X27,TRUE),"") | Z27: =IF(NOT($X27),"",IF($R27="文言",$U27,IF(入力基準日="","基準日を入力",IF($R27="日数",入力基準日+$S27+$T27-1,IF($R27="翌月10日",EOMONTH(入力基準日,0)+10,IF($R27="翌月末",EOMONTH(入力基準日,1),IF($R27="1か月後",EDATE(入力基準日,1),$U27)))))))
A28: 24 | B28: 退職所得の源泉徴収票／受給に関する申告書 | C28: 本人・法人 | D28: 退職 | O28: 有 | R28: 1か月後 | S28: 0 | V28: 給与システム | X28: =AND($B28<>"",入力区分<>"",OR($D28="両方",$D28=入力区分),OR($E28="",$E28=条件_社保),OR($F28="",$F28=条件_雇保),OR($G28="",$G28=条件_外国籍),OR($H28="",$H28=条件_特定技能),OR($I28="",$I28=条件_扶養),OR($J28="",$J28=条件_70歳以上),OR($K28="",$K28=条件_離職票要),OR($L28="",$L28=条件_特徴),OR($M28="",$M28=条件_共済),OR($N28="",$N28=条件_役職),OR($O28="",$O28=条件_退職金),OR($P28="",$P28=条件_障害者),OR($Q28="",$Q28=条件_解雇)) | Y28: =IF($X28,COUNTIF($X$5:$X28,TRUE),"") | Z28: =IF(NOT($X28),"",IF($R28="文言",$U28,IF(入力基準日="","基準日を入力",IF($R28="日数",入力基準日+$S28+$T28-1,IF($R28="翌月10日",EOMONTH(入力基準日,0)+10,IF($R28="翌月末",EOMONTH(入力基準日,1),IF($R28="1か月後",EDATE(入力基準日,1),$U28)))))))
A29: 25 | B29: 障害者解雇届 | C29: ハローワーク | D29: 退職 | P29: 有 | Q29: 有 | R29: 文言 | U29: 遅滞なく | V29: 紙 | X29: =AND($B29<>"",入力区分<>"",OR($D29="両方",$D29=入力区分),OR($E29="",$E29=条件_社保),OR($F29="",$F29=条件_雇保),OR($G29="",$G29=条件_外国籍),OR($H29="",$H29=条件_特定技能),OR($I29="",$I29=条件_扶養),OR($J29="",$J29=条件_70歳以上),OR($K29="",$K29=条件_離職票要),OR($L29="",$L29=条件_特徴),OR($M29="",$M29=条件_共済),OR($N29="",$N29=条件_役職),OR($O29="",$O29=条件_退職金),OR($P29="",$P29=条件_障害者),OR($Q29="",$Q29=条件_解雇)) | Y29: =IF($X29,COUNTIF($X$5:$X29,TRUE),"") | Z29: =IF(NOT($X29),"",IF($R29="文言",$U29,IF(入力基準日="","基準日を入力",IF($R29="日数",入力基準日+$S29+$T29-1,IF($R29="翌月10日",EOMONTH(入力基準日,0)+10,IF($R29="翌月末",EOMONTH(入力基準日,1),IF($R29="1か月後",EDATE(入力基準日,1),$U29)))))))
A30: 26 | B30: 退職証明書（請求があれば） | C30: 本人 | D30: 退職 | R30: 文言 | U30: 請求があれば遅滞なく | V30: 台帳から定型文書 | X30: =AND($B30<>"",入力区分<>"",OR($D30="両方",$D30=入力区分),OR($E30="",$E30=条件_社保),OR($F30="",$F30=条件_雇保),OR($G30="",$G30=条件_外国籍),OR($H30="",$H30=条件_特定技能),OR($I30="",$I30=条件_扶養),OR($J30="",$J30=条件_70歳以上),OR($K30="",$K30=条件_離職票要),OR($L30="",$L30=条件_特徴),OR($M30="",$M30=条件_共済),OR($N30="",$N30=条件_役職),OR($O30="",$O30=条件_退職金),OR($P30="",$P30=条件_障害者),OR($Q30="",$Q30=条件_解雇)) | Y30: =IF($X30,COUNTIF($X$5:$X30,TRUE),"") | Z30: =IF(NOT($X30),"",IF($R30="文言",$U30,IF(入力基準日="","基準日を入力",IF($R30="日数",入力基準日+$S30+$T30-1,IF($R30="翌月10日",EOMONTH(入力基準日,0)+10,IF($R30="翌月末",EOMONTH(入力基準日,1),IF($R30="1か月後",EDATE(入力基準日,1),$U30)))))))
X31: =AND($B31<>"",入力区分<>"",OR($D31="両方",$D31=入力区分),OR($E31="",$E31=条件_社保),OR($F31="",$F31=条件_雇保),OR($G31="",$G31=条件_外国籍),OR($H31="",$H31=条件_特定技能),OR($I31="",$I31=条件_扶養),OR($J31="",$J31=条件_70歳以上),OR($K31="",$K31=条件_離職票要),OR($L31="",$L31=条件_特徴),OR($M31="",$M31=条件_共済),OR($N31="",$N31=条件_役職),OR($O31="",$O31=条件_退職金),OR($P31="",$P31=条件_障害者),OR($Q31="",$Q31=条件_解雇)) | Y31: =IF($X31,COUNTIF($X$5:$X31,TRUE),"") | Z31: =IF(NOT($X31),"",IF($R31="文言",$U31,IF(入力基準日="","基準日を入力",IF($R31="日数",入力基準日+$S31+$T31-1,IF($R31="翌月10日",EOMONTH(入力基準日,0)+10,IF($R31="翌月末",EOMONTH(入力基準日,1),IF($R31="1か月後",EDATE(入力基準日,1),$U31)))))))
X32: =AND($B32<>"",入力区分<>"",OR($D32="両方",$D32=入力区分),OR($E32="",$E32=条件_社保),OR($F32="",$F32=条件_雇保),OR($G32="",$G32=条件_外国籍),OR($H32="",$H32=条件_特定技能),OR($I32="",$I32=条件_扶養),OR($J32="",$J32=条件_70歳以上),OR($K32="",$K32=条件_離職票要),OR($L32="",$L32=条件_特徴),OR($M32="",$M32=条件_共済),OR($N32="",$N32=条件_役職),OR($O32="",$O32=条件_退職金),OR($P32="",$P32=条件_障害者),OR($Q32="",$Q32=条件_解雇)) | Y32: =IF($X32,COUNTIF($X$5:$X32,TRUE),"") | Z32: =IF(NOT($X32),"",IF($R32="文言",$U32,IF(入力基準日="","基準日を入力",IF($R32="日数",入力基準日+$S32+$T32-1,IF($R32="翌月10日",EOMONTH(入力基準日,0)+10,IF($R32="翌月末",EOMONTH(入力基準日,1),IF($R32="1か月後",EDATE(入力基準日,1),$U32)))))))
X33: =AND($B33<>"",入力区分<>"",OR($D33="両方",$D33=入力区分),OR($E33="",$E33=条件_社保),OR($F33="",$F33=条件_雇保),OR($G33="",$G33=条件_外国籍),OR($H33="",$H33=条件_特定技能),OR($I33="",$I33=条件_扶養),OR($J33="",$J33=条件_70歳以上),OR($K33="",$K33=条件_離職票要),OR($L33="",$L33=条件_特徴),OR($M33="",$M33=条件_共済),OR($N33="",$N33=条件_役職),OR($O33="",$O33=条件_退職金),OR($P33="",$P33=条件_障害者),OR($Q33="",$Q33=条件_解雇)) | Y33: =IF($X33,COUNTIF($X$5:$X33,TRUE),"") | Z33: =IF(NOT($X33),"",IF($R33="文言",$U33,IF(入力基準日="","基準日を入力",IF($R33="日数",入力基準日+$S33+$T33-1,IF($R33="翌月10日",EOMONTH(入力基準日,0)+10,IF($R33="翌月末",EOMONTH(入力基準日,1),IF($R33="1か月後",EDATE(入力基準日,1),$U33)))))))
X34: =AND($B34<>"",入力区分<>"",OR($D34="両方",$D34=入力区分),OR($E34="",$E34=条件_社保),OR($F34="",$F34=条件_雇保),OR($G34="",$G34=条件_外国籍),OR($H34="",$H34=条件_特定技能),OR($I34="",$I34=条件_扶養),OR($J34="",$J34=条件_70歳以上),OR($K34="",$K34=条件_離職票要),OR($L34="",$L34=条件_特徴),OR($M34="",$M34=条件_共済),OR($N34="",$N34=条件_役職),OR($O34="",$O34=条件_退職金),OR($P34="",$P34=条件_障害者),OR($Q34="",$Q34=条件_解雇)) | Y34: =IF($X34,COUNTIF($X$5:$X34,TRUE),"") | Z34: =IF(NOT($X34),"",IF($R34="文言",$U34,IF(入力基準日="","基準日を入力",IF($R34="日数",入力基準日+$S34+$T34-1,IF($R34="翌月10日",EOMONTH(入力基準日,0)+10,IF($R34="翌月末",EOMONTH(入力基準日,1),IF($R34="1か月後",EDATE(入力基準日,1),$U34)))))))
X35: =AND($B35<>"",入力区分<>"",OR($D35="両方",$D35=入力区分),OR($E35="",$E35=条件_社保),OR($F35="",$F35=条件_雇保),OR($G35="",$G35=条件_外国籍),OR($H35="",$H35=条件_特定技能),OR($I35="",$I35=条件_扶養),OR($J35="",$J35=条件_70歳以上),OR($K35="",$K35=条件_離職票要),OR($L35="",$L35=条件_特徴),OR($M35="",$M35=条件_共済),OR($N35="",$N35=条件_役職),OR($O35="",$O35=条件_退職金),OR($P35="",$P35=条件_障害者),OR($Q35="",$Q35=条件_解雇)) | Y35: =IF($X35,COUNTIF($X$5:$X35,TRUE),"") | Z35: =IF(NOT($X35),"",IF($R35="文言",$U35,IF(入力基準日="","基準日を入力",IF($R35="日数",入力基準日+$S35+$T35-1,IF($R35="翌月10日",EOMONTH(入力基準日,0)+10,IF($R35="翌月末",EOMONTH(入力基準日,1),IF($R35="1か月後",EDATE(入力基準日,1),$U35)))))))
X36: =AND($B36<>"",入力区分<>"",OR($D36="両方",$D36=入力区分),OR($E36="",$E36=条件_社保),OR($F36="",$F36=条件_雇保),OR($G36="",$G36=条件_外国籍),OR($H36="",$H36=条件_特定技能),OR($I36="",$I36=条件_扶養),OR($J36="",$J36=条件_70歳以上),OR($K36="",$K36=条件_離職票要),OR($L36="",$L36=条件_特徴),OR($M36="",$M36=条件_共済),OR($N36="",$N36=条件_役職),OR($O36="",$O36=条件_退職金),OR($P36="",$P36=条件_障害者),OR($Q36="",$Q36=条件_解雇)) | Y36: =IF($X36,COUNTIF($X$5:$X36,TRUE),"") | Z36: =IF(NOT($X36),"",IF($R36="文言",$U36,IF(入力基準日="","基準日を入力",IF($R36="日数",入力基準日+$S36+$T36-1,IF($R36="翌月10日",EOMONTH(入力基準日,0)+10,IF($R36="翌月末",EOMONTH(入力基準日,1),IF($R36="1か月後",EDATE(入力基準日,1),$U36)))))))
X37: =AND($B37<>"",入力区分<>"",OR($D37="両方",$D37=入力区分),OR($E37="",$E37=条件_社保),OR($F37="",$F37=条件_雇保),OR($G37="",$G37=条件_外国籍),OR($H37="",$H37=条件_特定技能),OR($I37="",$I37=条件_扶養),OR($J37="",$J37=条件_70歳以上),OR($K37="",$K37=条件_離職票要),OR($L37="",$L37=条件_特徴),OR($M37="",$M37=条件_共済),OR($N37="",$N37=条件_役職),OR($O37="",$O37=条件_退職金),OR($P37="",$P37=条件_障害者),OR($Q37="",$Q37=条件_解雇)) | Y37: =IF($X37,COUNTIF($X$5:$X37,TRUE),"") | Z37: =IF(NOT($X37),"",IF($R37="文言",$U37,IF(入力基準日="","基準日を入力",IF($R37="日数",入力基準日+$S37+$T37-1,IF($R37="翌月10日",EOMONTH(入力基準日,0)+10,IF($R37="翌月末",EOMONTH(入力基準日,1),IF($R37="1か月後",EDATE(入力基準日,1),$U37)))))))
X38: =AND($B38<>"",入力区分<>"",OR($D38="両方",$D38=入力区分),OR($E38="",$E38=条件_社保),OR($F38="",$F38=条件_雇保),OR($G38="",$G38=条件_外国籍),OR($H38="",$H38=条件_特定技能),OR($I38="",$I38=条件_扶養),OR($J38="",$J38=条件_70歳以上),OR($K38="",$K38=条件_離職票要),OR($L38="",$L38=条件_特徴),OR($M38="",$M38=条件_共済),OR($N38="",$N38=条件_役職),OR($O38="",$O38=条件_退職金),OR($P38="",$P38=条件_障害者),OR($Q38="",$Q38=条件_解雇)) | Y38: =IF($X38,COUNTIF($X$5:$X38,TRUE),"") | Z38: =IF(NOT($X38),"",IF($R38="文言",$U38,IF(入力基準日="","基準日を入力",IF($R38="日数",入力基準日+$S38+$T38-1,IF($R38="翌月10日",EOMONTH(入力基準日,0)+10,IF($R38="翌月末",EOMONTH(入力基準日,1),IF($R38="1か月後",EDATE(入力基準日,1),$U38)))))))
X39: =AND($B39<>"",入力区分<>"",OR($D39="両方",$D39=入力区分),OR($E39="",$E39=条件_社保),OR($F39="",$F39=条件_雇保),OR($G39="",$G39=条件_外国籍),OR($H39="",$H39=条件_特定技能),OR($I39="",$I39=条件_扶養),OR($J39="",$J39=条件_70歳以上),OR($K39="",$K39=条件_離職票要),OR($L39="",$L39=条件_特徴),OR($M39="",$M39=条件_共済),OR($N39="",$N39=条件_役職),OR($O39="",$O39=条件_退職金),OR($P39="",$P39=条件_障害者),OR($Q39="",$Q39=条件_解雇)) | Y39: =IF($X39,COUNTIF($X$5:$X39,TRUE),"") | Z39: =IF(NOT($X39),"",IF($R39="文言",$U39,IF(入力基準日="","基準日を入力",IF($R39="日数",入力基準日+$S39+$T39-1,IF($R39="翌月10日",EOMONTH(入力基準日,0)+10,IF($R39="翌月末",EOMONTH(入力基準日,1),IF($R39="1か月後",EDATE(入力基準日,1),$U39)))))))
X40: =AND($B40<>"",入力区分<>"",OR($D40="両方",$D40=入力区分),OR($E40="",$E40=条件_社保),OR($F40="",$F40=条件_雇保),OR($G40="",$G40=条件_外国籍),OR($H40="",$H40=条件_特定技能),OR($I40="",$I40=条件_扶養),OR($J40="",$J40=条件_70歳以上),OR($K40="",$K40=条件_離職票要),OR($L40="",$L40=条件_特徴),OR($M40="",$M40=条件_共済),OR($N40="",$N40=条件_役職),OR($O40="",$O40=条件_退職金),OR($P40="",$P40=条件_障害者),OR($Q40="",$Q40=条件_解雇)) | Y40: =IF($X40,COUNTIF($X$5:$X40,TRUE),"") | Z40: =IF(NOT($X40),"",IF($R40="文言",$U40,IF(入力基準日="","基準日を入力",IF($R40="日数",入力基準日+$S40+$T40-1,IF($R40="翌月10日",EOMONTH(入力基準日,0)+10,IF($R40="翌月末",EOMONTH(入力基準日,1),IF($R40="1か月後",EDATE(入力基準日,1),$U40)))))))
X41: =AND($B41<>"",入力区分<>"",OR($D41="両方",$D41=入力区分),OR($E41="",$E41=条件_社保),OR($F41="",$F41=条件_雇保),OR($G41="",$G41=条件_外国籍),OR($H41="",$H41=条件_特定技能),OR($I41="",$I41=条件_扶養),OR($J41="",$J41=条件_70歳以上),OR($K41="",$K41=条件_離職票要),OR($L41="",$L41=条件_特徴),OR($M41="",$M41=条件_共済),OR($N41="",$N41=条件_役職),OR($O41="",$O41=条件_退職金),OR($P41="",$P41=条件_障害者),OR($Q41="",$Q41=条件_解雇)) | Y41: =IF($X41,COUNTIF($X$5:$X41,TRUE),"") | Z41: =IF(NOT($X41),"",IF($R41="文言",$U41,IF(入力基準日="","基準日を入力",IF($R41="日数",入力基準日+$S41+$T41-1,IF($R41="翌月10日",EOMONTH(入力基準日,0)+10,IF($R41="翌月末",EOMONTH(入力基準日,1),IF($R41="1か月後",EDATE(入力基準日,1),$U41)))))))
...

Sheet ログ
A1: ログ（出力の履歴）
A2: マクロが1行ずつ追記する。手で消さない
A4: 日時 | B4: ユーザー | C4: 届種別 | D4: 件数 | E4: ファイル | F4: 結果

Sheet 変更履歴
A1: 変更履歴
A3: 版 | B3: 日付 | C3: 変更者 | D3: 変更内容
A4: v1.0 | B4: 2026-10-29 | C4: （作成） | D4: 初版。チェックリスト（数式）、社保取得・喪失CSV、雇保取得・喪失の転記一覧。レイアウト定義の届書コード等はCSV仕様書で要確認（確定＝未）
